[2025-05-19T11:00:23.743+0000] {local_task_job_runner.py:123} INFO - ::group::Pre task execution logs
[2025-05-19T11:00:23.750+0000] {taskinstance.py:2612} INFO - Dependencies all met for dep_context=non-requeueable deps ti=<TaskInstance: csv_to_parquet.kafka_producer scheduled__2025-05-19T10:05:00+00:00 [queued]>
[2025-05-19T11:00:23.824+0000] {taskinstance.py:2612} INFO - Dependencies all met for dep_context=requeueable deps ti=<TaskInstance: csv_to_parquet.kafka_producer scheduled__2025-05-19T10:05:00+00:00 [queued]>
[2025-05-19T11:00:23.825+0000] {taskinstance.py:2865} INFO - Starting attempt 2 of 2
[2025-05-19T11:00:23.829+0000] {taskinstance.py:2888} INFO - Executing <Task(PythonOperator): kafka_producer> on 2025-05-19 10:05:00+00:00
[2025-05-19T11:00:23.832+0000] {standard_task_runner.py:72} INFO - Started process 1953 to run task
[2025-05-19T11:00:23.834+0000] {standard_task_runner.py:104} INFO - Running: ['***', 'tasks', 'run', 'csv_to_parquet', 'kafka_producer', 'scheduled__2025-05-19T10:05:00+00:00', '--job-id', '69', '--raw', '--subdir', 'DAGS_FOLDER/log_to_csv.py', '--cfg-path', '/tmp/tmpfpc_xclk']
[2025-05-19T11:00:23.834+0000] {standard_task_runner.py:105} INFO - Job 69: Subtask kafka_producer
[2025-05-19T11:00:23.852+0000] {task_command.py:467} INFO - Running <TaskInstance: csv_to_parquet.kafka_producer scheduled__2025-05-19T10:05:00+00:00 [running]> on host 8b6a4ce3396b
[2025-05-19T11:00:23.885+0000] {taskinstance.py:3131} INFO - Exporting env vars: AIRFLOW_CTX_DAG_OWNER='***' AIRFLOW_CTX_DAG_ID='csv_to_parquet' AIRFLOW_CTX_TASK_ID='kafka_producer' AIRFLOW_CTX_EXECUTION_DATE='2025-05-19T10:05:00+00:00' AIRFLOW_CTX_TRY_NUMBER='2' AIRFLOW_CTX_DAG_RUN_ID='scheduled__2025-05-19T10:05:00+00:00'
[2025-05-19T11:00:23.885+0000] {taskinstance.py:731} INFO - ::endgroup::
[2025-05-19T11:00:23.892+0000] {conn.py:396} INFO - <BrokerConnection client_id=kafka-python-producer-1, node_id=bootstrap-0 host=host.docker.internal:9092 <connecting> [IPv4 ('192.168.65.254', 9092)]>: connecting to host.docker.internal:9092 [('192.168.65.254', 9092) IPv4]
[2025-05-19T11:00:23.894+0000] {conn.py:618} INFO - <BrokerConnection client_id=kafka-python-producer-1, node_id=bootstrap-0 host=host.docker.internal:9092 <checking_api_versions_recv> [IPv4 ('192.168.65.254', 9092)]>: Broker version identified as 2.6
[2025-05-19T11:00:23.894+0000] {conn.py:457} INFO - <BrokerConnection client_id=kafka-python-producer-1, node_id=bootstrap-0 host=host.docker.internal:9092 <connected> [IPv4 ('192.168.65.254', 9092)]>: Connection complete.
[2025-05-19T11:00:23.998+0000] {conn.py:396} INFO - <BrokerConnection client_id=kafka-python-producer-1, node_id=1 host=172.16.24.224:9092 <connecting> [IPv4 ('172.16.24.224', 9092)]>: connecting to 172.16.24.224:9092 [('172.16.24.224', 9092) IPv4]
[2025-05-19T11:00:23.999+0000] {conn.py:429} ERROR - <BrokerConnection client_id=kafka-python-producer-1, node_id=1 host=172.16.24.224:9092 <connecting> [IPv4 ('172.16.24.224', 9092)]>: Connect attempt returned error 111. Disconnecting.
[2025-05-19T11:00:23.999+0000] {conn.py:945} ERROR - <BrokerConnection client_id=kafka-python-producer-1, node_id=1 host=172.16.24.224:9092 <connecting> [IPv4 ('172.16.24.224', 9092)]>: Closing connection. KafkaConnectionError: 111 ECONNREFUSED
[2025-05-19T11:00:23.999+0000] {client_async.py:388} WARNING - Node 1 connection failed -- refreshing metadata
[2025-05-19T11:00:24.052+0000] {conn.py:396} INFO - <BrokerConnection client_id=kafka-python-producer-1, node_id=1 host=172.16.24.224:9092 <connecting> [IPv4 ('172.16.24.224', 9092)]>: connecting to 172.16.24.224:9092 [('172.16.24.224', 9092) IPv4]
[2025-05-19T11:00:24.053+0000] {conn.py:429} ERROR - <BrokerConnection client_id=kafka-python-producer-1, node_id=1 host=172.16.24.224:9092 <connecting> [IPv4 ('172.16.24.224', 9092)]>: Connect attempt returned error 111. Disconnecting.
[2025-05-19T11:00:24.053+0000] {conn.py:945} ERROR - <BrokerConnection client_id=kafka-python-producer-1, node_id=1 host=172.16.24.224:9092 <connecting> [IPv4 ('172.16.24.224', 9092)]>: Closing connection. KafkaConnectionError: 111 ECONNREFUSED
[2025-05-19T11:00:24.053+0000] {client_async.py:388} WARNING - Node 1 connection failed -- refreshing metadata
[2025-05-19T11:00:24.157+0000] {conn.py:396} INFO - <BrokerConnection client_id=kafka-python-producer-1, node_id=1 host=172.16.24.224:9092 <connecting> [IPv4 ('172.16.24.224', 9092)]>: connecting to 172.16.24.224:9092 [('172.16.24.224', 9092) IPv4]
[2025-05-19T11:00:24.158+0000] {conn.py:429} ERROR - <BrokerConnection client_id=kafka-python-producer-1, node_id=1 host=172.16.24.224:9092 <connecting> [IPv4 ('172.16.24.224', 9092)]>: Connect attempt returned error 111. Disconnecting.
[2025-05-19T11:00:24.158+0000] {conn.py:945} ERROR - <BrokerConnection client_id=kafka-python-producer-1, node_id=1 host=172.16.24.224:9092 <connecting> [IPv4 ('172.16.24.224', 9092)]>: Closing connection. KafkaConnectionError: 111 ECONNREFUSED
[2025-05-19T11:00:24.158+0000] {client_async.py:388} WARNING - Node 1 connection failed -- refreshing metadata
[2025-05-19T11:00:24.392+0000] {conn.py:396} INFO - <BrokerConnection client_id=kafka-python-producer-1, node_id=1 host=172.16.24.224:9092 <connecting> [IPv4 ('172.16.24.224', 9092)]>: connecting to 172.16.24.224:9092 [('172.16.24.224', 9092) IPv4]
[2025-05-19T11:00:24.393+0000] {conn.py:429} ERROR - <BrokerConnection client_id=kafka-python-producer-1, node_id=1 host=172.16.24.224:9092 <connecting> [IPv4 ('172.16.24.224', 9092)]>: Connect attempt returned error 111. Disconnecting.
[2025-05-19T11:00:24.393+0000] {conn.py:945} ERROR - <BrokerConnection client_id=kafka-python-producer-1, node_id=1 host=172.16.24.224:9092 <connecting> [IPv4 ('172.16.24.224', 9092)]>: Closing connection. KafkaConnectionError: 111 ECONNREFUSED
[2025-05-19T11:00:24.393+0000] {client_async.py:388} WARNING - Node 1 connection failed -- refreshing metadata
[2025-05-19T11:00:24.797+0000] {conn.py:396} INFO - <BrokerConnection client_id=kafka-python-producer-1, node_id=1 host=172.16.24.224:9092 <connecting> [IPv4 ('172.16.24.224', 9092)]>: connecting to 172.16.24.224:9092 [('172.16.24.224', 9092) IPv4]
[2025-05-19T11:00:24.800+0000] {conn.py:429} ERROR - <BrokerConnection client_id=kafka-python-producer-1, node_id=1 host=172.16.24.224:9092 <connecting> [IPv4 ('172.16.24.224', 9092)]>: Connect attempt returned error 111. Disconnecting.
[2025-05-19T11:00:24.801+0000] {conn.py:945} ERROR - <BrokerConnection client_id=kafka-python-producer-1, node_id=1 host=172.16.24.224:9092 <connecting> [IPv4 ('172.16.24.224', 9092)]>: Closing connection. KafkaConnectionError: 111 ECONNREFUSED
[2025-05-19T11:00:24.801+0000] {client_async.py:388} WARNING - Node 1 connection failed -- refreshing metadata
[2025-05-19T11:00:25.573+0000] {conn.py:396} INFO - <BrokerConnection client_id=kafka-python-producer-1, node_id=1 host=172.16.24.224:9092 <connecting> [IPv4 ('172.16.24.224', 9092)]>: connecting to 172.16.24.224:9092 [('172.16.24.224', 9092) IPv4]
[2025-05-19T11:00:25.576+0000] {conn.py:429} ERROR - <BrokerConnection client_id=kafka-python-producer-1, node_id=1 host=172.16.24.224:9092 <connecting> [IPv4 ('172.16.24.224', 9092)]>: Connect attempt returned error 111. Disconnecting.
[2025-05-19T11:00:25.577+0000] {conn.py:945} ERROR - <BrokerConnection client_id=kafka-python-producer-1, node_id=1 host=172.16.24.224:9092 <connecting> [IPv4 ('172.16.24.224', 9092)]>: Closing connection. KafkaConnectionError: 111 ECONNREFUSED
[2025-05-19T11:00:25.578+0000] {client_async.py:388} WARNING - Node 1 connection failed -- refreshing metadata
[2025-05-19T11:00:27.139+0000] {conn.py:396} INFO - <BrokerConnection client_id=kafka-python-producer-1, node_id=1 host=172.16.24.224:9092 <connecting> [IPv4 ('172.16.24.224', 9092)]>: connecting to 172.16.24.224:9092 [('172.16.24.224', 9092) IPv4]
[2025-05-19T11:00:27.142+0000] {conn.py:429} ERROR - <BrokerConnection client_id=kafka-python-producer-1, node_id=1 host=172.16.24.224:9092 <connecting> [IPv4 ('172.16.24.224', 9092)]>: Connect attempt returned error 111. Disconnecting.
[2025-05-19T11:00:27.143+0000] {conn.py:945} ERROR - <BrokerConnection client_id=kafka-python-producer-1, node_id=1 host=172.16.24.224:9092 <connecting> [IPv4 ('172.16.24.224', 9092)]>: Closing connection. KafkaConnectionError: 111 ECONNREFUSED
[2025-05-19T11:00:27.144+0000] {client_async.py:388} WARNING - Node 1 connection failed -- refreshing metadata
[2025-05-19T11:00:30.265+0000] {conn.py:396} INFO - <BrokerConnection client_id=kafka-python-producer-1, node_id=1 host=172.16.24.224:9092 <connecting> [IPv4 ('172.16.24.224', 9092)]>: connecting to 172.16.24.224:9092 [('172.16.24.224', 9092) IPv4]
[2025-05-19T11:00:30.268+0000] {conn.py:429} ERROR - <BrokerConnection client_id=kafka-python-producer-1, node_id=1 host=172.16.24.224:9092 <connecting> [IPv4 ('172.16.24.224', 9092)]>: Connect attempt returned error 111. Disconnecting.
[2025-05-19T11:00:30.269+0000] {conn.py:945} ERROR - <BrokerConnection client_id=kafka-python-producer-1, node_id=1 host=172.16.24.224:9092 <connecting> [IPv4 ('172.16.24.224', 9092)]>: Closing connection. KafkaConnectionError: 111 ECONNREFUSED
[2025-05-19T11:00:30.270+0000] {client_async.py:388} WARNING - Node 1 connection failed -- refreshing metadata
[2025-05-19T11:00:36.632+0000] {conn.py:396} INFO - <BrokerConnection client_id=kafka-python-producer-1, node_id=1 host=172.16.24.224:9092 <connecting> [IPv4 ('172.16.24.224', 9092)]>: connecting to 172.16.24.224:9092 [('172.16.24.224', 9092) IPv4]
[2025-05-19T11:00:36.633+0000] {conn.py:429} ERROR - <BrokerConnection client_id=kafka-python-producer-1, node_id=1 host=172.16.24.224:9092 <connecting> [IPv4 ('172.16.24.224', 9092)]>: Connect attempt returned error 111. Disconnecting.
[2025-05-19T11:00:36.633+0000] {conn.py:945} ERROR - <BrokerConnection client_id=kafka-python-producer-1, node_id=1 host=172.16.24.224:9092 <connecting> [IPv4 ('172.16.24.224', 9092)]>: Closing connection. KafkaConnectionError: 111 ECONNREFUSED
[2025-05-19T11:00:36.634+0000] {client_async.py:388} WARNING - Node 1 connection failed -- refreshing metadata
[2025-05-19T11:13:52.704+0000] {client_async.py:1148} INFO - Closing idle connection bootstrap-0, last active 808807 ms ago
[2025-05-19T11:13:52.704+0000] {conn.py:945} INFO - <BrokerConnection client_id=kafka-python-producer-1, node_id=bootstrap-0 host=host.docker.internal:9092 <connected> [IPv4 ('192.168.65.254', 9092)]>: Closing connection. 
[2025-05-19T11:13:52.705+0000] {conn.py:396} INFO - <BrokerConnection client_id=kafka-python-producer-1, node_id=1 host=172.16.24.224:9092 <connecting> [IPv4 ('172.16.24.224', 9092)]>: connecting to 172.16.24.224:9092 [('172.16.24.224', 9092) IPv4]
[2025-05-19T11:13:54.366+0000] {job.py:229} INFO - Heartbeat recovered after 790.35 seconds
[2025-05-19T11:14:29.175+0000] {taskinstance.py:3310} ERROR - Task failed with exception
Traceback (most recent call last):
  File "/home/airflow/.local/lib/python3.10/site-packages/airflow/models/taskinstance.py", line 762, in _execute_task
    result = _execute_callable(context=context, **execute_callable_kwargs)
  File "/home/airflow/.local/lib/python3.10/site-packages/airflow/models/taskinstance.py", line 733, in _execute_callable
    return ExecutionCallableRunner(
  File "/home/airflow/.local/lib/python3.10/site-packages/airflow/utils/operator_helpers.py", line 252, in run
    return self.func(*args, **kwargs)
  File "/home/airflow/.local/lib/python3.10/site-packages/airflow/models/baseoperator.py", line 406, in wrapper
    return func(self, *args, **kwargs)
  File "/home/airflow/.local/lib/python3.10/site-packages/airflow/operators/python.py", line 238, in execute
    return_value = self.execute_callable()
  File "/home/airflow/.local/lib/python3.10/site-packages/airflow/operators/python.py", line 256, in execute_callable
    return runner.run(*self.op_args, **self.op_kwargs)
  File "/home/airflow/.local/lib/python3.10/site-packages/airflow/utils/operator_helpers.py", line 252, in run
    return self.func(*args, **kwargs)
  File "/opt/airflow/dags/log_to_csv.py", line 46, in kafka_producer
    producer.send('airflowtest', event)
  File "/home/airflow/.local/lib/python3.10/site-packages/kafka/producer/kafka.py", line 840, in send
    self._wait_on_metadata(topic, timer.timeout_ms)
  File "/home/airflow/.local/lib/python3.10/site-packages/kafka/producer/kafka.py", line 964, in _wait_on_metadata
    raise Errors.KafkaTimeoutError(
kafka.errors.KafkaTimeoutError: KafkaTimeoutError: Failed to update metadata after 59999000.0 secs.
[2025-05-19T11:14:29.193+0000] {taskinstance.py:1225} INFO - Marking task as FAILED. dag_id=csv_to_parquet, task_id=kafka_producer, run_id=scheduled__2025-05-19T10:05:00+00:00, execution_date=20250519T100500, start_date=20250519T110023, end_date=20250519T111429
[2025-05-19T11:14:29.206+0000] {taskinstance.py:340} INFO - ::group::Post task execution logs
[2025-05-19T11:14:29.206+0000] {standard_task_runner.py:124} ERROR - Failed to execute job 69 for task kafka_producer (KafkaTimeoutError: Failed to update metadata after 59999000.0 secs.; 1953)
Traceback (most recent call last):
  File "/home/airflow/.local/lib/python3.10/site-packages/airflow/task/task_runner/standard_task_runner.py", line 117, in _start_by_fork
    ret = args.func(args, dag=self.dag)
  File "/home/airflow/.local/lib/python3.10/site-packages/airflow/cli/cli_config.py", line 49, in command
    return func(*args, **kwargs)
  File "/home/airflow/.local/lib/python3.10/site-packages/airflow/utils/cli.py", line 115, in wrapper
    return f(*args, **kwargs)
  File "/home/airflow/.local/lib/python3.10/site-packages/airflow/cli/commands/task_command.py", line 483, in task_run
    task_return_code = _run_task_by_selected_method(args, _dag, ti)
  File "/home/airflow/.local/lib/python3.10/site-packages/airflow/cli/commands/task_command.py", line 256, in _run_task_by_selected_method
    return _run_raw_task(args, ti)
  File "/home/airflow/.local/lib/python3.10/site-packages/airflow/cli/commands/task_command.py", line 341, in _run_raw_task
    return ti._run_raw_task(
  File "/home/airflow/.local/lib/python3.10/site-packages/airflow/utils/session.py", line 97, in wrapper
    return func(*args, session=session, **kwargs)
  File "/home/airflow/.local/lib/python3.10/site-packages/airflow/models/taskinstance.py", line 3004, in _run_raw_task
    return _run_raw_task(
  File "/home/airflow/.local/lib/python3.10/site-packages/airflow/models/taskinstance.py", line 273, in _run_raw_task
    TaskInstance._execute_task_with_callbacks(
  File "/home/airflow/.local/lib/python3.10/site-packages/airflow/models/taskinstance.py", line 3158, in _execute_task_with_callbacks
    result = self._execute_task(context, task_orig)
  File "/home/airflow/.local/lib/python3.10/site-packages/airflow/models/taskinstance.py", line 3182, in _execute_task
    return _execute_task(self, context, task_orig)
  File "/home/airflow/.local/lib/python3.10/site-packages/airflow/models/taskinstance.py", line 762, in _execute_task
    result = _execute_callable(context=context, **execute_callable_kwargs)
  File "/home/airflow/.local/lib/python3.10/site-packages/airflow/models/taskinstance.py", line 733, in _execute_callable
    return ExecutionCallableRunner(
  File "/home/airflow/.local/lib/python3.10/site-packages/airflow/utils/operator_helpers.py", line 252, in run
    return self.func(*args, **kwargs)
  File "/home/airflow/.local/lib/python3.10/site-packages/airflow/models/baseoperator.py", line 406, in wrapper
    return func(self, *args, **kwargs)
  File "/home/airflow/.local/lib/python3.10/site-packages/airflow/operators/python.py", line 238, in execute
    return_value = self.execute_callable()
  File "/home/airflow/.local/lib/python3.10/site-packages/airflow/operators/python.py", line 256, in execute_callable
    return runner.run(*self.op_args, **self.op_kwargs)
  File "/home/airflow/.local/lib/python3.10/site-packages/airflow/utils/operator_helpers.py", line 252, in run
    return self.func(*args, **kwargs)
  File "/opt/airflow/dags/log_to_csv.py", line 46, in kafka_producer
    producer.send('airflowtest', event)
  File "/home/airflow/.local/lib/python3.10/site-packages/kafka/producer/kafka.py", line 840, in send
    self._wait_on_metadata(topic, timer.timeout_ms)
  File "/home/airflow/.local/lib/python3.10/site-packages/kafka/producer/kafka.py", line 964, in _wait_on_metadata
    raise Errors.KafkaTimeoutError(
kafka.errors.KafkaTimeoutError: KafkaTimeoutError: Failed to update metadata after 59999000.0 secs.
[2025-05-19T11:14:29.234+0000] {local_task_job_runner.py:266} INFO - Task exited with return code 1
[2025-05-19T11:14:29.250+0000] {taskinstance.py:3900} INFO - 0 downstream tasks scheduled from follow-on schedule check
[2025-05-19T11:14:29.252+0000] {local_task_job_runner.py:245} INFO - ::endgroup::
