[2025-05-20T05:54:13.985+0000] {local_task_job_runner.py:123} INFO - ::group::Pre task execution logs
[2025-05-20T05:54:13.991+0000] {taskinstance.py:2612} INFO - Dependencies all met for dep_context=non-requeueable deps ti=<TaskInstance: kafka_to_minio_to_spark.upload_postgres scheduled__2025-05-20T01:00:00+00:00 [queued]>
[2025-05-20T05:54:13.994+0000] {taskinstance.py:2612} INFO - Dependencies all met for dep_context=requeueable deps ti=<TaskInstance: kafka_to_minio_to_spark.upload_postgres scheduled__2025-05-20T01:00:00+00:00 [queued]>
[2025-05-20T05:54:13.994+0000] {taskinstance.py:2865} INFO - Starting attempt 2 of 3
[2025-05-20T05:54:13.998+0000] {taskinstance.py:2888} INFO - Executing <Task(PostgresOperator): upload_postgres> on 2025-05-20 01:00:00+00:00
[2025-05-20T05:54:14.000+0000] {standard_task_runner.py:72} INFO - Started process 2025 to run task
[2025-05-20T05:54:14.002+0000] {standard_task_runner.py:104} INFO - Running: ['***', 'tasks', 'run', 'kafka_to_minio_to_spark', 'upload_postgres', 'scheduled__2025-05-20T01:00:00+00:00', '--job-id', '136', '--raw', '--subdir', 'DAGS_FOLDER/testlog_ml.py', '--cfg-path', '/tmp/tmpu8vtjqs4']
[2025-05-20T05:54:14.003+0000] {standard_task_runner.py:105} INFO - Job 136: Subtask upload_postgres
[2025-05-20T05:54:14.022+0000] {task_command.py:467} INFO - Running <TaskInstance: kafka_to_minio_to_spark.upload_postgres scheduled__2025-05-20T01:00:00+00:00 [running]> on host 91a46f1a1993
[2025-05-20T05:54:14.145+0000] {taskinstance.py:3131} INFO - Exporting env vars: AIRFLOW_CTX_DAG_OWNER='***' AIRFLOW_CTX_DAG_ID='kafka_to_minio_to_spark' AIRFLOW_CTX_TASK_ID='upload_postgres' AIRFLOW_CTX_EXECUTION_DATE='2025-05-20T01:00:00+00:00' AIRFLOW_CTX_TRY_NUMBER='2' AIRFLOW_CTX_DAG_RUN_ID='scheduled__2025-05-20T01:00:00+00:00'
[2025-05-20T05:54:14.145+0000] {taskinstance.py:731} INFO - ::endgroup::
[2025-05-20T05:54:14.149+0000] {sql.py:266} INFO - Executing: 
        INSERT INTO test_db (key, value)
        VALUES ('hello', 'world')
        
[2025-05-20T05:54:14.152+0000] {base.py:84} INFO - Retrieving connection 'postgres'
[2025-05-20T05:54:14.155+0000] {base.py:84} INFO - Retrieving connection 'postgres'
[2025-05-20T05:54:14.159+0000] {sql.py:509} INFO - Running statement: 
        INSERT INTO test_db (key, value)
        VALUES ('hello', 'world')
        , parameters: None
[2025-05-20T05:54:14.161+0000] {taskinstance.py:3310} ERROR - Task failed with exception
Traceback (most recent call last):
  File "/home/airflow/.local/lib/python3.10/site-packages/airflow/models/taskinstance.py", line 762, in _execute_task
    result = _execute_callable(context=context, **execute_callable_kwargs)
  File "/home/airflow/.local/lib/python3.10/site-packages/airflow/models/taskinstance.py", line 733, in _execute_callable
    return ExecutionCallableRunner(
  File "/home/airflow/.local/lib/python3.10/site-packages/airflow/utils/operator_helpers.py", line 252, in run
    return self.func(*args, **kwargs)
  File "/home/airflow/.local/lib/python3.10/site-packages/airflow/models/baseoperator.py", line 406, in wrapper
    return func(self, *args, **kwargs)
  File "/home/airflow/.local/lib/python3.10/site-packages/airflow/providers/common/sql/operators/sql.py", line 272, in execute
    output = hook.run(
  File "/home/airflow/.local/lib/python3.10/site-packages/airflow/providers/common/sql/hooks/sql.py", line 456, in run
    self._run_command(cur, sql_statement, parameters)
  File "/home/airflow/.local/lib/python3.10/site-packages/airflow/providers/common/sql/hooks/sql.py", line 514, in _run_command
    cur.execute(sql_statement)
psycopg2.errors.UndefinedTable: relation "test_db" does not exist
LINE 2:         INSERT INTO test_db (key, value)
                            ^

[2025-05-20T05:54:14.165+0000] {taskinstance.py:1225} INFO - Marking task as UP_FOR_RETRY. dag_id=kafka_to_minio_to_spark, task_id=upload_postgres, run_id=scheduled__2025-05-20T01:00:00+00:00, execution_date=20250520T010000, start_date=20250520T055413, end_date=20250520T055414
[2025-05-20T05:54:14.170+0000] {taskinstance.py:340} INFO - ::group::Post task execution logs
[2025-05-20T05:54:14.170+0000] {standard_task_runner.py:124} ERROR - Failed to execute job 136 for task upload_postgres (relation "test_db" does not exist
LINE 2:         INSERT INTO test_db (key, value)
                            ^
; 2025)
Traceback (most recent call last):
  File "/home/airflow/.local/lib/python3.10/site-packages/airflow/task/task_runner/standard_task_runner.py", line 117, in _start_by_fork
    ret = args.func(args, dag=self.dag)
  File "/home/airflow/.local/lib/python3.10/site-packages/airflow/cli/cli_config.py", line 49, in command
    return func(*args, **kwargs)
  File "/home/airflow/.local/lib/python3.10/site-packages/airflow/utils/cli.py", line 115, in wrapper
    return f(*args, **kwargs)
  File "/home/airflow/.local/lib/python3.10/site-packages/airflow/cli/commands/task_command.py", line 483, in task_run
    task_return_code = _run_task_by_selected_method(args, _dag, ti)
  File "/home/airflow/.local/lib/python3.10/site-packages/airflow/cli/commands/task_command.py", line 256, in _run_task_by_selected_method
    return _run_raw_task(args, ti)
  File "/home/airflow/.local/lib/python3.10/site-packages/airflow/cli/commands/task_command.py", line 341, in _run_raw_task
    return ti._run_raw_task(
  File "/home/airflow/.local/lib/python3.10/site-packages/airflow/utils/session.py", line 97, in wrapper
    return func(*args, session=session, **kwargs)
  File "/home/airflow/.local/lib/python3.10/site-packages/airflow/models/taskinstance.py", line 3004, in _run_raw_task
    return _run_raw_task(
  File "/home/airflow/.local/lib/python3.10/site-packages/airflow/models/taskinstance.py", line 273, in _run_raw_task
    TaskInstance._execute_task_with_callbacks(
  File "/home/airflow/.local/lib/python3.10/site-packages/airflow/models/taskinstance.py", line 3158, in _execute_task_with_callbacks
    result = self._execute_task(context, task_orig)
  File "/home/airflow/.local/lib/python3.10/site-packages/airflow/models/taskinstance.py", line 3182, in _execute_task
    return _execute_task(self, context, task_orig)
  File "/home/airflow/.local/lib/python3.10/site-packages/airflow/models/taskinstance.py", line 762, in _execute_task
    result = _execute_callable(context=context, **execute_callable_kwargs)
  File "/home/airflow/.local/lib/python3.10/site-packages/airflow/models/taskinstance.py", line 733, in _execute_callable
    return ExecutionCallableRunner(
  File "/home/airflow/.local/lib/python3.10/site-packages/airflow/utils/operator_helpers.py", line 252, in run
    return self.func(*args, **kwargs)
  File "/home/airflow/.local/lib/python3.10/site-packages/airflow/models/baseoperator.py", line 406, in wrapper
    return func(self, *args, **kwargs)
  File "/home/airflow/.local/lib/python3.10/site-packages/airflow/providers/common/sql/operators/sql.py", line 272, in execute
    output = hook.run(
  File "/home/airflow/.local/lib/python3.10/site-packages/airflow/providers/common/sql/hooks/sql.py", line 456, in run
    self._run_command(cur, sql_statement, parameters)
  File "/home/airflow/.local/lib/python3.10/site-packages/airflow/providers/common/sql/hooks/sql.py", line 514, in _run_command
    cur.execute(sql_statement)
psycopg2.errors.UndefinedTable: relation "test_db" does not exist
LINE 2:         INSERT INTO test_db (key, value)
                            ^

[2025-05-20T05:54:14.185+0000] {local_task_job_runner.py:266} INFO - Task exited with return code 1
[2025-05-20T05:54:14.192+0000] {taskinstance.py:3900} INFO - 0 downstream tasks scheduled from follow-on schedule check
[2025-05-20T05:54:14.193+0000] {local_task_job_runner.py:245} INFO - ::endgroup::
