[2025-05-22T10:52:05.092+0000] {local_task_job_runner.py:123} INFO - ::group::Pre task execution logs
[2025-05-22T10:52:05.098+0000] {taskinstance.py:2612} INFO - Dependencies all met for dep_context=non-requeueable deps ti=<TaskInstance: kafka_to_minio_to_spark.check_minio_file scheduled__2025-05-21T16:00:00+00:00 [queued]>
[2025-05-22T10:52:05.100+0000] {taskinstance.py:2612} INFO - Dependencies all met for dep_context=requeueable deps ti=<TaskInstance: kafka_to_minio_to_spark.check_minio_file scheduled__2025-05-21T16:00:00+00:00 [queued]>
[2025-05-22T10:52:05.100+0000] {taskinstance.py:2865} INFO - Starting attempt 8 of 10
[2025-05-22T10:52:05.104+0000] {taskinstance.py:2888} INFO - Executing <Task(S3KeySensor): check_minio_file> on 2025-05-21 16:00:00+00:00
[2025-05-22T10:52:05.106+0000] {standard_task_runner.py:72} INFO - Started process 95 to run task
[2025-05-22T10:52:05.108+0000] {standard_task_runner.py:104} INFO - Running: ['***', 'tasks', 'run', 'kafka_to_minio_to_spark', 'check_minio_file', 'scheduled__2025-05-21T16:00:00+00:00', '--job-id', '238', '--raw', '--subdir', 'DAGS_FOLDER/testlog_ml.py', '--cfg-path', '/tmp/tmpa6n3e8ft']
[2025-05-22T10:52:05.109+0000] {standard_task_runner.py:105} INFO - Job 238: Subtask check_minio_file
[2025-05-22T10:52:05.126+0000] {task_command.py:467} INFO - Running <TaskInstance: kafka_to_minio_to_spark.check_minio_file scheduled__2025-05-21T16:00:00+00:00 [running]> on host b589638bb236
[2025-05-22T10:52:05.150+0000] {taskinstance.py:3131} INFO - Exporting env vars: AIRFLOW_CTX_DAG_OWNER='***' AIRFLOW_CTX_DAG_ID='kafka_to_minio_to_spark' AIRFLOW_CTX_TASK_ID='check_minio_file' AIRFLOW_CTX_EXECUTION_DATE='2025-05-21T16:00:00+00:00' AIRFLOW_CTX_TRY_NUMBER='8' AIRFLOW_CTX_DAG_RUN_ID='scheduled__2025-05-21T16:00:00+00:00'
[2025-05-22T10:52:05.151+0000] {taskinstance.py:731} INFO - ::endgroup::
[2025-05-22T10:52:05.156+0000] {baseoperator.py:405} WARNING - S3KeySensor.execute cannot be called outside TaskInstance!
[2025-05-22T10:52:05.156+0000] {s3.py:118} INFO - Poking for key : s3://user-log-ml/2025-05-21_*.csv
[2025-05-22T10:52:05.160+0000] {base.py:84} INFO - Retrieving connection 'minio'
[2025-05-22T10:52:05.160+0000] {connection_wrapper.py:388} INFO - AWS Connection (conn_id='minio', conn_type='aws') credentials retrieved from login and password.
[2025-05-22T10:52:10.353+0000] {s3.py:118} INFO - Poking for key : s3://user-log-ml/2025-05-21_*.csv
[2025-05-22T10:52:15.370+0000] {s3.py:118} INFO - Poking for key : s3://user-log-ml/2025-05-21_*.csv
[2025-05-22T10:52:20.389+0000] {s3.py:118} INFO - Poking for key : s3://user-log-ml/2025-05-21_*.csv
[2025-05-22T10:52:25.411+0000] {s3.py:118} INFO - Poking for key : s3://user-log-ml/2025-05-21_*.csv
[2025-05-22T10:52:30.431+0000] {s3.py:118} INFO - Poking for key : s3://user-log-ml/2025-05-21_*.csv
[2025-05-22T10:52:35.456+0000] {s3.py:118} INFO - Poking for key : s3://user-log-ml/2025-05-21_*.csv
[2025-05-22T10:52:40.479+0000] {s3.py:118} INFO - Poking for key : s3://user-log-ml/2025-05-21_*.csv
[2025-05-22T10:52:45.492+0000] {s3.py:118} INFO - Poking for key : s3://user-log-ml/2025-05-21_*.csv
[2025-05-22T10:52:50.415+0000] {local_task_job_runner.py:346} WARNING - State of this instance has been externally set to restarting. Terminating instance.
[2025-05-22T10:52:50.415+0000] {local_task_job_runner.py:245} INFO - ::endgroup::
[2025-05-22T10:52:50.416+0000] {process_utils.py:132} INFO - Sending 15 to group 95. PIDs of all processes in the group: [95]
[2025-05-22T10:52:50.417+0000] {process_utils.py:87} INFO - Sending the signal 15 to group 95
[2025-05-22T10:52:50.417+0000] {taskinstance.py:3092} ERROR - Received SIGTERM. Terminating subprocesses.
[2025-05-22T10:52:50.422+0000] {taskinstance.py:3310} ERROR - Task failed with exception
Traceback (most recent call last):
  File "/home/airflow/.local/lib/python3.10/site-packages/airflow/models/taskinstance.py", line 762, in _execute_task
    result = _execute_callable(context=context, **execute_callable_kwargs)
  File "/home/airflow/.local/lib/python3.10/site-packages/airflow/models/taskinstance.py", line 733, in _execute_callable
    return ExecutionCallableRunner(
  File "/home/airflow/.local/lib/python3.10/site-packages/airflow/utils/operator_helpers.py", line 252, in run
    return self.func(*args, **kwargs)
  File "/home/airflow/.local/lib/python3.10/site-packages/airflow/models/baseoperator.py", line 406, in wrapper
    return func(self, *args, **kwargs)
  File "/home/airflow/.local/lib/python3.10/site-packages/airflow/providers/amazon/aws/sensors/s3.py", line 189, in execute
    super().execute(context)
  File "/home/airflow/.local/lib/python3.10/site-packages/airflow/models/baseoperator.py", line 406, in wrapper
    return func(self, *args, **kwargs)
  File "/home/airflow/.local/lib/python3.10/site-packages/airflow/sensors/base.py", line 334, in execute
    time.sleep(self._get_next_poke_interval(started_at, run_duration, poke_count))
  File "/home/airflow/.local/lib/python3.10/site-packages/airflow/models/taskinstance.py", line 3094, in signal_handler
    raise AirflowTaskTerminated("Task received SIGTERM signal")
airflow.exceptions.AirflowTaskTerminated: Task received SIGTERM signal
[2025-05-22T10:52:50.423+0000] {taskinstance.py:1225} INFO - Marking task as UP_FOR_RETRY. dag_id=kafka_to_minio_to_spark, task_id=check_minio_file, run_id=scheduled__2025-05-21T16:00:00+00:00, execution_date=20250521T160000, start_date=20250522T105205, end_date=20250522T105250
[2025-05-22T10:52:50.429+0000] {taskinstance.py:340} INFO - ::group::Post task execution logs
[2025-05-22T10:52:50.449+0000] {process_utils.py:80} INFO - Process psutil.Process(pid=95, status='terminated', exitcode=2, started='10:52:04') (95) terminated with exit code 2
