[2025-05-22T06:43:33.558+0000] {local_task_job_runner.py:123} INFO - ::group::Pre task execution logs
[2025-05-22T06:43:33.564+0000] {taskinstance.py:2612} INFO - Dependencies all met for dep_context=non-requeueable deps ti=<TaskInstance: kafka_to_minio_to_spark.check_minio_file scheduled__2025-05-21T16:00:00+00:00 [queued]>
[2025-05-22T06:43:33.567+0000] {taskinstance.py:2612} INFO - Dependencies all met for dep_context=requeueable deps ti=<TaskInstance: kafka_to_minio_to_spark.check_minio_file scheduled__2025-05-21T16:00:00+00:00 [queued]>
[2025-05-22T06:43:33.567+0000] {taskinstance.py:2865} INFO - Starting attempt 4 of 5
[2025-05-22T06:43:33.571+0000] {taskinstance.py:2888} INFO - Executing <Task(S3KeySensor): check_minio_file> on 2025-05-21 16:00:00+00:00
[2025-05-22T06:43:33.573+0000] {standard_task_runner.py:72} INFO - Started process 787 to run task
[2025-05-22T06:43:33.575+0000] {standard_task_runner.py:104} INFO - Running: ['***', 'tasks', 'run', 'kafka_to_minio_to_spark', 'check_minio_file', 'scheduled__2025-05-21T16:00:00+00:00', '--job-id', '208', '--raw', '--subdir', 'DAGS_FOLDER/testlog_ml.py', '--cfg-path', '/tmp/tmph_mr8d9x']
[2025-05-22T06:43:33.576+0000] {standard_task_runner.py:105} INFO - Job 208: Subtask check_minio_file
[2025-05-22T06:43:33.595+0000] {task_command.py:467} INFO - Running <TaskInstance: kafka_to_minio_to_spark.check_minio_file scheduled__2025-05-21T16:00:00+00:00 [running]> on host d1f65538eb5f
[2025-05-22T06:43:33.623+0000] {taskinstance.py:3131} INFO - Exporting env vars: AIRFLOW_CTX_DAG_OWNER='***' AIRFLOW_CTX_DAG_ID='kafka_to_minio_to_spark' AIRFLOW_CTX_TASK_ID='check_minio_file' AIRFLOW_CTX_EXECUTION_DATE='2025-05-21T16:00:00+00:00' AIRFLOW_CTX_TRY_NUMBER='4' AIRFLOW_CTX_DAG_RUN_ID='scheduled__2025-05-21T16:00:00+00:00'
[2025-05-22T06:43:33.623+0000] {taskinstance.py:731} INFO - ::endgroup::
[2025-05-22T06:43:33.628+0000] {baseoperator.py:405} WARNING - S3KeySensor.execute cannot be called outside TaskInstance!
[2025-05-22T06:43:33.628+0000] {s3.py:118} INFO - Poking for key : s3://user-log-ml/2025-05-21_*.csv
[2025-05-22T06:43:33.632+0000] {base.py:84} INFO - Retrieving connection 'minio'
[2025-05-22T06:43:33.633+0000] {connection_wrapper.py:388} INFO - AWS Connection (conn_id='minio', conn_type='aws') credentials retrieved from login and password.
[2025-05-22T06:43:33.806+0000] {taskinstance.py:3310} ERROR - Task failed with exception
Traceback (most recent call last):
  File "/home/airflow/.local/lib/python3.10/site-packages/airflow/models/taskinstance.py", line 762, in _execute_task
    result = _execute_callable(context=context, **execute_callable_kwargs)
  File "/home/airflow/.local/lib/python3.10/site-packages/airflow/models/taskinstance.py", line 733, in _execute_callable
    return ExecutionCallableRunner(
  File "/home/airflow/.local/lib/python3.10/site-packages/airflow/utils/operator_helpers.py", line 252, in run
    return self.func(*args, **kwargs)
  File "/home/airflow/.local/lib/python3.10/site-packages/airflow/models/baseoperator.py", line 406, in wrapper
    return func(self, *args, **kwargs)
  File "/home/airflow/.local/lib/python3.10/site-packages/airflow/providers/amazon/aws/sensors/s3.py", line 189, in execute
    super().execute(context)
  File "/home/airflow/.local/lib/python3.10/site-packages/airflow/models/baseoperator.py", line 406, in wrapper
    return func(self, *args, **kwargs)
  File "/home/airflow/.local/lib/python3.10/site-packages/airflow/sensors/base.py", line 306, in execute
    raise e
  File "/home/airflow/.local/lib/python3.10/site-packages/airflow/sensors/base.py", line 286, in execute
    poke_return = self.poke(context)
  File "/home/airflow/.local/lib/python3.10/site-packages/airflow/providers/amazon/aws/sensors/s3.py", line 182, in poke
    return self._check_key(self.bucket_key, context=context)
  File "/home/airflow/.local/lib/python3.10/site-packages/airflow/providers/amazon/aws/sensors/s3.py", line 128, in _check_key
    keys = self.hook.get_file_metadata(prefix, bucket_name)
  File "/home/airflow/.local/lib/python3.10/site-packages/airflow/providers/amazon/aws/hooks/s3.py", line 132, in wrapper
    return func(*bound_args.args, **bound_args.kwargs)
  File "/home/airflow/.local/lib/python3.10/site-packages/airflow/providers/amazon/aws/hooks/s3.py", line 900, in get_file_metadata
    for page in response:
  File "/home/airflow/.local/lib/python3.10/site-packages/botocore/paginate.py", line 269, in __iter__
    response = self._make_request(current_kwargs)
  File "/home/airflow/.local/lib/python3.10/site-packages/botocore/paginate.py", line 357, in _make_request
    return self._method(**current_kwargs)
  File "/home/airflow/.local/lib/python3.10/site-packages/botocore/client.py", line 565, in _api_call
    return self._make_api_call(operation_name, kwargs)
  File "/home/airflow/.local/lib/python3.10/site-packages/botocore/client.py", line 1017, in _make_api_call
    raise error_class(parsed_response, operation_name)
botocore.errorfactory.NoSuchBucket: An error occurred (NoSuchBucket) when calling the ListObjectsV2 operation: The specified bucket does not exist
[2025-05-22T06:43:33.810+0000] {taskinstance.py:1225} INFO - Marking task as UP_FOR_RETRY. dag_id=kafka_to_minio_to_spark, task_id=check_minio_file, run_id=scheduled__2025-05-21T16:00:00+00:00, execution_date=20250521T160000, start_date=20250522T064333, end_date=20250522T064333
[2025-05-22T06:43:33.815+0000] {taskinstance.py:340} INFO - ::group::Post task execution logs
[2025-05-22T06:43:33.815+0000] {standard_task_runner.py:124} ERROR - Failed to execute job 208 for task check_minio_file (An error occurred (NoSuchBucket) when calling the ListObjectsV2 operation: The specified bucket does not exist; 787)
Traceback (most recent call last):
  File "/home/airflow/.local/lib/python3.10/site-packages/airflow/task/task_runner/standard_task_runner.py", line 117, in _start_by_fork
    ret = args.func(args, dag=self.dag)
  File "/home/airflow/.local/lib/python3.10/site-packages/airflow/cli/cli_config.py", line 49, in command
    return func(*args, **kwargs)
  File "/home/airflow/.local/lib/python3.10/site-packages/airflow/utils/cli.py", line 115, in wrapper
    return f(*args, **kwargs)
  File "/home/airflow/.local/lib/python3.10/site-packages/airflow/cli/commands/task_command.py", line 483, in task_run
    task_return_code = _run_task_by_selected_method(args, _dag, ti)
  File "/home/airflow/.local/lib/python3.10/site-packages/airflow/cli/commands/task_command.py", line 256, in _run_task_by_selected_method
    return _run_raw_task(args, ti)
  File "/home/airflow/.local/lib/python3.10/site-packages/airflow/cli/commands/task_command.py", line 341, in _run_raw_task
    return ti._run_raw_task(
  File "/home/airflow/.local/lib/python3.10/site-packages/airflow/utils/session.py", line 97, in wrapper
    return func(*args, session=session, **kwargs)
  File "/home/airflow/.local/lib/python3.10/site-packages/airflow/models/taskinstance.py", line 3004, in _run_raw_task
    return _run_raw_task(
  File "/home/airflow/.local/lib/python3.10/site-packages/airflow/models/taskinstance.py", line 273, in _run_raw_task
    TaskInstance._execute_task_with_callbacks(
  File "/home/airflow/.local/lib/python3.10/site-packages/airflow/models/taskinstance.py", line 3158, in _execute_task_with_callbacks
    result = self._execute_task(context, task_orig)
  File "/home/airflow/.local/lib/python3.10/site-packages/airflow/models/taskinstance.py", line 3182, in _execute_task
    return _execute_task(self, context, task_orig)
  File "/home/airflow/.local/lib/python3.10/site-packages/airflow/models/taskinstance.py", line 762, in _execute_task
    result = _execute_callable(context=context, **execute_callable_kwargs)
  File "/home/airflow/.local/lib/python3.10/site-packages/airflow/models/taskinstance.py", line 733, in _execute_callable
    return ExecutionCallableRunner(
  File "/home/airflow/.local/lib/python3.10/site-packages/airflow/utils/operator_helpers.py", line 252, in run
    return self.func(*args, **kwargs)
  File "/home/airflow/.local/lib/python3.10/site-packages/airflow/models/baseoperator.py", line 406, in wrapper
    return func(self, *args, **kwargs)
  File "/home/airflow/.local/lib/python3.10/site-packages/airflow/providers/amazon/aws/sensors/s3.py", line 189, in execute
    super().execute(context)
  File "/home/airflow/.local/lib/python3.10/site-packages/airflow/models/baseoperator.py", line 406, in wrapper
    return func(self, *args, **kwargs)
  File "/home/airflow/.local/lib/python3.10/site-packages/airflow/sensors/base.py", line 306, in execute
    raise e
  File "/home/airflow/.local/lib/python3.10/site-packages/airflow/sensors/base.py", line 286, in execute
    poke_return = self.poke(context)
  File "/home/airflow/.local/lib/python3.10/site-packages/airflow/providers/amazon/aws/sensors/s3.py", line 182, in poke
    return self._check_key(self.bucket_key, context=context)
  File "/home/airflow/.local/lib/python3.10/site-packages/airflow/providers/amazon/aws/sensors/s3.py", line 128, in _check_key
    keys = self.hook.get_file_metadata(prefix, bucket_name)
  File "/home/airflow/.local/lib/python3.10/site-packages/airflow/providers/amazon/aws/hooks/s3.py", line 132, in wrapper
    return func(*bound_args.args, **bound_args.kwargs)
  File "/home/airflow/.local/lib/python3.10/site-packages/airflow/providers/amazon/aws/hooks/s3.py", line 900, in get_file_metadata
    for page in response:
  File "/home/airflow/.local/lib/python3.10/site-packages/botocore/paginate.py", line 269, in __iter__
    response = self._make_request(current_kwargs)
  File "/home/airflow/.local/lib/python3.10/site-packages/botocore/paginate.py", line 357, in _make_request
    return self._method(**current_kwargs)
  File "/home/airflow/.local/lib/python3.10/site-packages/botocore/client.py", line 565, in _api_call
    return self._make_api_call(operation_name, kwargs)
  File "/home/airflow/.local/lib/python3.10/site-packages/botocore/client.py", line 1017, in _make_api_call
    raise error_class(parsed_response, operation_name)
botocore.errorfactory.NoSuchBucket: An error occurred (NoSuchBucket) when calling the ListObjectsV2 operation: The specified bucket does not exist
[2025-05-22T06:43:33.849+0000] {local_task_job_runner.py:266} INFO - Task exited with return code 1
[2025-05-22T06:43:33.858+0000] {taskinstance.py:3900} INFO - 0 downstream tasks scheduled from follow-on schedule check
[2025-05-22T06:43:33.859+0000] {local_task_job_runner.py:245} INFO - ::endgroup::
