[2025-05-23T02:04:44.681+0000] {local_task_job_runner.py:123} INFO - ::group::Pre task execution logs
[2025-05-23T02:04:44.687+0000] {taskinstance.py:2612} INFO - Dependencies all met for dep_context=non-requeueable deps ti=<TaskInstance: kafka_to_minio_to_spark.kafka_consumer scheduled__2025-05-22T16:00:00+00:00 [queued]>
[2025-05-23T02:04:44.689+0000] {taskinstance.py:2612} INFO - Dependencies all met for dep_context=requeueable deps ti=<TaskInstance: kafka_to_minio_to_spark.kafka_consumer scheduled__2025-05-22T16:00:00+00:00 [queued]>
[2025-05-23T02:04:44.690+0000] {taskinstance.py:2865} INFO - Starting attempt 5 of 7
[2025-05-23T02:04:44.694+0000] {taskinstance.py:2888} INFO - Executing <Task(PythonOperator): kafka_consumer> on 2025-05-22 16:00:00+00:00
[2025-05-23T02:04:44.696+0000] {standard_task_runner.py:72} INFO - Started process 510 to run task
[2025-05-23T02:04:44.698+0000] {standard_task_runner.py:104} INFO - Running: ['***', 'tasks', 'run', 'kafka_to_minio_to_spark', 'kafka_consumer', 'scheduled__2025-05-22T16:00:00+00:00', '--job-id', '353', '--raw', '--subdir', 'DAGS_FOLDER/testlog_ml.py', '--cfg-path', '/tmp/tmp55bn5a89']
[2025-05-23T02:04:44.699+0000] {standard_task_runner.py:105} INFO - Job 353: Subtask kafka_consumer
[2025-05-23T02:04:44.718+0000] {task_command.py:467} INFO - Running <TaskInstance: kafka_to_minio_to_spark.kafka_consumer scheduled__2025-05-22T16:00:00+00:00 [running]> on host 3e84bbc47e1b
[2025-05-23T02:04:44.744+0000] {taskinstance.py:3131} INFO - Exporting env vars: AIRFLOW_CTX_DAG_OWNER='***' AIRFLOW_CTX_DAG_ID='kafka_to_minio_to_spark' AIRFLOW_CTX_TASK_ID='kafka_consumer' AIRFLOW_CTX_EXECUTION_DATE='2025-05-22T16:00:00+00:00' AIRFLOW_CTX_TRY_NUMBER='5' AIRFLOW_CTX_DAG_RUN_ID='scheduled__2025-05-22T16:00:00+00:00'
[2025-05-23T02:04:44.744+0000] {taskinstance.py:731} INFO - ::endgroup::
[2025-05-23T02:04:44.749+0000] {conn.py:380} INFO - <BrokerConnection node_id=bootstrap-0 host=3.37.147.123:9092 <connecting> [IPv4 ('3.37.147.123', 9092)]>: connecting to 3.37.147.123:9092 [('3.37.147.123', 9092) IPv4]
[2025-05-23T02:04:44.750+0000] {conn.py:1205} INFO - Probing node bootstrap-0 broker version
[2025-05-23T02:04:44.787+0000] {conn.py:410} INFO - <BrokerConnection node_id=bootstrap-0 host=3.37.147.123:9092 <connecting> [IPv4 ('3.37.147.123', 9092)]>: Connection complete.
[2025-05-23T02:04:44.923+0000] {conn.py:1267} INFO - Broker version identified as 2.5.0
[2025-05-23T02:04:44.923+0000] {conn.py:1268} INFO - Set configuration api_version=(2, 5, 0) to skip auto check_version requests on startup
[2025-05-23T02:04:44.924+0000] {subscription_state.py:171} INFO - Updating subscribed topics to: ('video-action-events',)
[2025-05-23T02:04:44.925+0000] {logging_mixin.py:190} INFO - ‚úÖ consumer started, waiting for messages....
[2025-05-23T02:04:45.021+0000] {cluster.py:371} INFO - Group coordinator for a is ('coordinator-1', '3.37.147.123', 9092, None)
[2025-05-23T02:04:45.023+0000] {base.py:693} INFO - Discovered coordinator coordinator-1 for group a
[2025-05-23T02:04:45.024+0000] {base.py:741} INFO - Starting new heartbeat thread
[2025-05-23T02:04:45.026+0000] {consumer.py:348} INFO - Revoking previously assigned partitions () for group a
[2025-05-23T02:04:45.028+0000] {conn.py:380} INFO - <BrokerConnection node_id=coordinator-1 host=3.37.147.123:9092 <connecting> [IPv4 ('3.37.147.123', 9092)]>: connecting to 3.37.147.123:9092 [('3.37.147.123', 9092) IPv4]
[2025-05-23T02:04:45.131+0000] {conn.py:410} INFO - <BrokerConnection node_id=coordinator-1 host=3.37.147.123:9092 <connecting> [IPv4 ('3.37.147.123', 9092)]>: Connection complete.
[2025-05-23T02:04:45.133+0000] {conn.py:919} INFO - <BrokerConnection node_id=bootstrap-0 host=3.37.147.123:9092 <connected> [IPv4 ('3.37.147.123', 9092)]>: Closing connection. 
[2025-05-23T02:04:45.236+0000] {base.py:450} INFO - (Re-)joining group a
[2025-05-23T02:04:48.253+0000] {base.py:521} INFO - Elected group leader -- performing partition assignments using range
[2025-05-23T02:04:48.256+0000] {conn.py:380} INFO - <BrokerConnection node_id=1 host=3.37.147.123:9092 <connecting> [IPv4 ('3.37.147.123', 9092)]>: connecting to 3.37.147.123:9092 [('3.37.147.123', 9092) IPv4]
[2025-05-23T02:04:48.264+0000] {base.py:335} INFO - Successfully joined group a with generation 1
[2025-05-23T02:04:48.265+0000] {subscription_state.py:257} INFO - Updated partition assignment: [('video-action-events', 0)]
[2025-05-23T02:04:48.266+0000] {consumer.py:245} INFO - Setting newly assigned partitions (('video-action-events', 0),) for group a
[2025-05-23T02:04:48.267+0000] {conn.py:410} INFO - <BrokerConnection node_id=1 host=3.37.147.123:9092 <connecting> [IPv4 ('3.37.147.123', 9092)]>: Connection complete.
[2025-05-23T02:04:48.398+0000] {logging_mixin.py:190} INFO - üì• Received: page:None
[2025-05-23T02:04:48.410+0000] {logging_mixin.py:190} INFO - üì• Received: page:None
[2025-05-23T02:04:48.424+0000] {logging_mixin.py:190} INFO - üì• Received: page:None
[2025-05-23T02:04:48.434+0000] {logging_mixin.py:190} INFO - üì• Received: page:None
[2025-05-23T02:04:48.442+0000] {logging_mixin.py:190} INFO - üì• Received: page:None
[2025-05-23T02:04:48.451+0000] {logging_mixin.py:190} INFO - üì• Received: page:None
[2025-05-23T02:04:48.461+0000] {logging_mixin.py:190} INFO - üì• Received: page:None
[2025-05-23T02:04:48.473+0000] {logging_mixin.py:190} INFO - üì• Received: page:None
[2025-05-23T02:04:48.484+0000] {logging_mixin.py:190} INFO - üì• Received: page:None
[2025-05-23T02:04:48.496+0000] {logging_mixin.py:190} INFO - üì• Received: page:None
[2025-05-23T02:04:48.507+0000] {logging_mixin.py:190} INFO - üì• Received: page:None
[2025-05-23T02:04:48.518+0000] {logging_mixin.py:190} INFO - ‚úÖMinio connected
[2025-05-23T02:04:48.525+0000] {base.py:84} INFO - Retrieving connection 'minio'
[2025-05-23T02:04:48.525+0000] {connection_wrapper.py:388} INFO - AWS Connection (conn_id='minio', conn_type='aws') credentials retrieved from login and password.
[2025-05-23T02:04:57.282+0000] {logging_mixin.py:190} INFO - ‚ùå DAG failed due to : Could not connect to the endpoint URL: "http://3.37.147.123:9000/user-action-log"
[2025-05-23T02:04:57.282+0000] {base.py:748} INFO - Stopping heartbeat thread
[2025-05-23T02:04:57.282+0000] {base.py:773} INFO - Leaving consumer group (a).
[2025-05-23T02:04:57.291+0000] {conn.py:919} INFO - <BrokerConnection node_id=coordinator-1 host=3.37.147.123:9092 <connected> [IPv4 ('3.37.147.123', 9092)]>: Closing connection. 
[2025-05-23T02:04:57.291+0000] {conn.py:919} INFO - <BrokerConnection node_id=1 host=3.37.147.123:9092 <connected> [IPv4 ('3.37.147.123', 9092)]>: Closing connection. 
[2025-05-23T02:04:57.291+0000] {taskinstance.py:3310} ERROR - Task failed with exception
Traceback (most recent call last):
  File "/home/airflow/.local/lib/python3.10/site-packages/urllib3/connection.py", line 196, in _new_conn
    sock = connection.create_connection(
  File "/home/airflow/.local/lib/python3.10/site-packages/urllib3/util/connection.py", line 85, in create_connection
    raise err
  File "/home/airflow/.local/lib/python3.10/site-packages/urllib3/util/connection.py", line 73, in create_connection
    sock.connect(sa)
ConnectionRefusedError: [Errno 111] Connection refused

The above exception was the direct cause of the following exception:

Traceback (most recent call last):
  File "/home/airflow/.local/lib/python3.10/site-packages/botocore/httpsession.py", line 464, in send
    urllib_response = conn.urlopen(
  File "/home/airflow/.local/lib/python3.10/site-packages/urllib3/connectionpool.py", line 843, in urlopen
    retries = retries.increment(
  File "/home/airflow/.local/lib/python3.10/site-packages/urllib3/util/retry.py", line 449, in increment
    raise reraise(type(error), error, _stacktrace)
  File "/home/airflow/.local/lib/python3.10/site-packages/urllib3/util/util.py", line 39, in reraise
    raise value
  File "/home/airflow/.local/lib/python3.10/site-packages/urllib3/connectionpool.py", line 789, in urlopen
    response = self._make_request(
  File "/home/airflow/.local/lib/python3.10/site-packages/urllib3/connectionpool.py", line 495, in _make_request
    conn.request(
  File "/home/airflow/.local/lib/python3.10/site-packages/botocore/awsrequest.py", line 96, in request
    rval = super().request(method, url, body, headers, *args, **kwargs)
  File "/home/airflow/.local/lib/python3.10/site-packages/urllib3/connection.py", line 398, in request
    self.endheaders()
  File "/usr/local/lib/python3.10/http/client.py", line 1278, in endheaders
    self._send_output(message_body, encode_chunked=encode_chunked)
  File "/home/airflow/.local/lib/python3.10/site-packages/botocore/awsrequest.py", line 123, in _send_output
    self.send(msg)
  File "/home/airflow/.local/lib/python3.10/site-packages/botocore/awsrequest.py", line 223, in send
    return super().send(str)
  File "/usr/local/lib/python3.10/http/client.py", line 976, in send
    self.connect()
  File "/home/airflow/.local/lib/python3.10/site-packages/urllib3/connection.py", line 236, in connect
    self.sock = self._new_conn()
  File "/home/airflow/.local/lib/python3.10/site-packages/urllib3/connection.py", line 211, in _new_conn
    raise NewConnectionError(
urllib3.exceptions.NewConnectionError: <botocore.awsrequest.AWSHTTPConnection object at 0xffff65cc9ff0>: Failed to establish a new connection: [Errno 111] Connection refused

During handling of the above exception, another exception occurred:

Traceback (most recent call last):
  File "/home/airflow/.local/lib/python3.10/site-packages/airflow/models/taskinstance.py", line 762, in _execute_task
    result = _execute_callable(context=context, **execute_callable_kwargs)
  File "/home/airflow/.local/lib/python3.10/site-packages/airflow/models/taskinstance.py", line 733, in _execute_callable
    return ExecutionCallableRunner(
  File "/home/airflow/.local/lib/python3.10/site-packages/airflow/utils/operator_helpers.py", line 252, in run
    return self.func(*args, **kwargs)
  File "/home/airflow/.local/lib/python3.10/site-packages/airflow/models/baseoperator.py", line 406, in wrapper
    return func(self, *args, **kwargs)
  File "/home/airflow/.local/lib/python3.10/site-packages/airflow/operators/python.py", line 238, in execute
    return_value = self.execute_callable()
  File "/home/airflow/.local/lib/python3.10/site-packages/airflow/operators/python.py", line 256, in execute_callable
    return runner.run(*self.op_args, **self.op_kwargs)
  File "/home/airflow/.local/lib/python3.10/site-packages/airflow/utils/operator_helpers.py", line 252, in run
    return self.func(*args, **kwargs)
  File "/opt/airflow/dags/testlog_ml.py", line 147, in kafka_consumer
    raise e
  File "/opt/airflow/dags/testlog_ml.py", line 130, in kafka_consumer
    if not s3_hook.check_for_bucket(bucket_name):
  File "/home/airflow/.local/lib/python3.10/site-packages/airflow/providers/amazon/aws/hooks/s3.py", line 132, in wrapper
    return func(*bound_args.args, **bound_args.kwargs)
  File "/home/airflow/.local/lib/python3.10/site-packages/airflow/providers/amazon/aws/hooks/s3.py", line 311, in check_for_bucket
    self.get_conn().head_bucket(Bucket=bucket_name)
  File "/home/airflow/.local/lib/python3.10/site-packages/botocore/client.py", line 565, in _api_call
    return self._make_api_call(operation_name, kwargs)
  File "/home/airflow/.local/lib/python3.10/site-packages/botocore/client.py", line 999, in _make_api_call
    http, parsed_response = self._make_request(
  File "/home/airflow/.local/lib/python3.10/site-packages/botocore/client.py", line 1023, in _make_request
    return self._endpoint.make_request(operation_model, request_dict)
  File "/home/airflow/.local/lib/python3.10/site-packages/botocore/endpoint.py", line 119, in make_request
    return self._send_request(request_dict, operation_model)
  File "/home/airflow/.local/lib/python3.10/site-packages/botocore/endpoint.py", line 200, in _send_request
    while self._needs_retry(
  File "/home/airflow/.local/lib/python3.10/site-packages/botocore/endpoint.py", line 352, in _needs_retry
    responses = self._event_emitter.emit(
  File "/home/airflow/.local/lib/python3.10/site-packages/botocore/hooks.py", line 412, in emit
    return self._emitter.emit(aliased_event_name, **kwargs)
  File "/home/airflow/.local/lib/python3.10/site-packages/botocore/hooks.py", line 256, in emit
    return self._emit(event_name, kwargs)
  File "/home/airflow/.local/lib/python3.10/site-packages/botocore/hooks.py", line 239, in _emit
    response = handler(**kwargs)
  File "/home/airflow/.local/lib/python3.10/site-packages/botocore/retryhandler.py", line 207, in __call__
    if self._checker(**checker_kwargs):
  File "/home/airflow/.local/lib/python3.10/site-packages/botocore/retryhandler.py", line 284, in __call__
    should_retry = self._should_retry(
  File "/home/airflow/.local/lib/python3.10/site-packages/botocore/retryhandler.py", line 320, in _should_retry
    return self._checker(attempt_number, response, caught_exception)
  File "/home/airflow/.local/lib/python3.10/site-packages/botocore/retryhandler.py", line 363, in __call__
    checker_response = checker(
  File "/home/airflow/.local/lib/python3.10/site-packages/botocore/retryhandler.py", line 247, in __call__
    return self._check_caught_exception(
  File "/home/airflow/.local/lib/python3.10/site-packages/botocore/retryhandler.py", line 416, in _check_caught_exception
    raise caught_exception
  File "/home/airflow/.local/lib/python3.10/site-packages/botocore/endpoint.py", line 279, in _do_get_response
    http_response = self._send(request)
  File "/home/airflow/.local/lib/python3.10/site-packages/botocore/endpoint.py", line 375, in _send
    return self.http_session.send(request)
  File "/home/airflow/.local/lib/python3.10/site-packages/botocore/httpsession.py", line 493, in send
    raise EndpointConnectionError(endpoint_url=request.url, error=e)
botocore.exceptions.EndpointConnectionError: Could not connect to the endpoint URL: "http://3.37.147.123:9000/user-action-log"
[2025-05-23T02:04:57.297+0000] {taskinstance.py:1225} INFO - Marking task as UP_FOR_RETRY. dag_id=kafka_to_minio_to_spark, task_id=kafka_consumer, run_id=scheduled__2025-05-22T16:00:00+00:00, execution_date=20250522T160000, start_date=20250523T020444, end_date=20250523T020457
[2025-05-23T02:04:57.303+0000] {taskinstance.py:340} INFO - ::group::Post task execution logs
[2025-05-23T02:04:57.303+0000] {standard_task_runner.py:124} ERROR - Failed to execute job 353 for task kafka_consumer (Could not connect to the endpoint URL: "http://3.37.147.123:9000/user-action-log"; 510)
Traceback (most recent call last):
  File "/home/airflow/.local/lib/python3.10/site-packages/urllib3/connection.py", line 196, in _new_conn
    sock = connection.create_connection(
  File "/home/airflow/.local/lib/python3.10/site-packages/urllib3/util/connection.py", line 85, in create_connection
    raise err
  File "/home/airflow/.local/lib/python3.10/site-packages/urllib3/util/connection.py", line 73, in create_connection
    sock.connect(sa)
ConnectionRefusedError: [Errno 111] Connection refused

The above exception was the direct cause of the following exception:

Traceback (most recent call last):
  File "/home/airflow/.local/lib/python3.10/site-packages/botocore/httpsession.py", line 464, in send
    urllib_response = conn.urlopen(
  File "/home/airflow/.local/lib/python3.10/site-packages/urllib3/connectionpool.py", line 843, in urlopen
    retries = retries.increment(
  File "/home/airflow/.local/lib/python3.10/site-packages/urllib3/util/retry.py", line 449, in increment
    raise reraise(type(error), error, _stacktrace)
  File "/home/airflow/.local/lib/python3.10/site-packages/urllib3/util/util.py", line 39, in reraise
    raise value
  File "/home/airflow/.local/lib/python3.10/site-packages/urllib3/connectionpool.py", line 789, in urlopen
    response = self._make_request(
  File "/home/airflow/.local/lib/python3.10/site-packages/urllib3/connectionpool.py", line 495, in _make_request
    conn.request(
  File "/home/airflow/.local/lib/python3.10/site-packages/botocore/awsrequest.py", line 96, in request
    rval = super().request(method, url, body, headers, *args, **kwargs)
  File "/home/airflow/.local/lib/python3.10/site-packages/urllib3/connection.py", line 398, in request
    self.endheaders()
  File "/usr/local/lib/python3.10/http/client.py", line 1278, in endheaders
    self._send_output(message_body, encode_chunked=encode_chunked)
  File "/home/airflow/.local/lib/python3.10/site-packages/botocore/awsrequest.py", line 123, in _send_output
    self.send(msg)
  File "/home/airflow/.local/lib/python3.10/site-packages/botocore/awsrequest.py", line 223, in send
    return super().send(str)
  File "/usr/local/lib/python3.10/http/client.py", line 976, in send
    self.connect()
  File "/home/airflow/.local/lib/python3.10/site-packages/urllib3/connection.py", line 236, in connect
    self.sock = self._new_conn()
  File "/home/airflow/.local/lib/python3.10/site-packages/urllib3/connection.py", line 211, in _new_conn
    raise NewConnectionError(
urllib3.exceptions.NewConnectionError: <botocore.awsrequest.AWSHTTPConnection object at 0xffff65cc9ff0>: Failed to establish a new connection: [Errno 111] Connection refused

During handling of the above exception, another exception occurred:

Traceback (most recent call last):
  File "/home/airflow/.local/lib/python3.10/site-packages/airflow/task/task_runner/standard_task_runner.py", line 117, in _start_by_fork
    ret = args.func(args, dag=self.dag)
  File "/home/airflow/.local/lib/python3.10/site-packages/airflow/cli/cli_config.py", line 49, in command
    return func(*args, **kwargs)
  File "/home/airflow/.local/lib/python3.10/site-packages/airflow/utils/cli.py", line 115, in wrapper
    return f(*args, **kwargs)
  File "/home/airflow/.local/lib/python3.10/site-packages/airflow/cli/commands/task_command.py", line 483, in task_run
    task_return_code = _run_task_by_selected_method(args, _dag, ti)
  File "/home/airflow/.local/lib/python3.10/site-packages/airflow/cli/commands/task_command.py", line 256, in _run_task_by_selected_method
    return _run_raw_task(args, ti)
  File "/home/airflow/.local/lib/python3.10/site-packages/airflow/cli/commands/task_command.py", line 341, in _run_raw_task
    return ti._run_raw_task(
  File "/home/airflow/.local/lib/python3.10/site-packages/airflow/utils/session.py", line 97, in wrapper
    return func(*args, session=session, **kwargs)
  File "/home/airflow/.local/lib/python3.10/site-packages/airflow/models/taskinstance.py", line 3004, in _run_raw_task
    return _run_raw_task(
  File "/home/airflow/.local/lib/python3.10/site-packages/airflow/models/taskinstance.py", line 273, in _run_raw_task
    TaskInstance._execute_task_with_callbacks(
  File "/home/airflow/.local/lib/python3.10/site-packages/airflow/models/taskinstance.py", line 3158, in _execute_task_with_callbacks
    result = self._execute_task(context, task_orig)
  File "/home/airflow/.local/lib/python3.10/site-packages/airflow/models/taskinstance.py", line 3182, in _execute_task
    return _execute_task(self, context, task_orig)
  File "/home/airflow/.local/lib/python3.10/site-packages/airflow/models/taskinstance.py", line 762, in _execute_task
    result = _execute_callable(context=context, **execute_callable_kwargs)
  File "/home/airflow/.local/lib/python3.10/site-packages/airflow/models/taskinstance.py", line 733, in _execute_callable
    return ExecutionCallableRunner(
  File "/home/airflow/.local/lib/python3.10/site-packages/airflow/utils/operator_helpers.py", line 252, in run
    return self.func(*args, **kwargs)
  File "/home/airflow/.local/lib/python3.10/site-packages/airflow/models/baseoperator.py", line 406, in wrapper
    return func(self, *args, **kwargs)
  File "/home/airflow/.local/lib/python3.10/site-packages/airflow/operators/python.py", line 238, in execute
    return_value = self.execute_callable()
  File "/home/airflow/.local/lib/python3.10/site-packages/airflow/operators/python.py", line 256, in execute_callable
    return runner.run(*self.op_args, **self.op_kwargs)
  File "/home/airflow/.local/lib/python3.10/site-packages/airflow/utils/operator_helpers.py", line 252, in run
    return self.func(*args, **kwargs)
  File "/opt/airflow/dags/testlog_ml.py", line 147, in kafka_consumer
    raise e
  File "/opt/airflow/dags/testlog_ml.py", line 130, in kafka_consumer
    if not s3_hook.check_for_bucket(bucket_name):
  File "/home/airflow/.local/lib/python3.10/site-packages/airflow/providers/amazon/aws/hooks/s3.py", line 132, in wrapper
    return func(*bound_args.args, **bound_args.kwargs)
  File "/home/airflow/.local/lib/python3.10/site-packages/airflow/providers/amazon/aws/hooks/s3.py", line 311, in check_for_bucket
    self.get_conn().head_bucket(Bucket=bucket_name)
  File "/home/airflow/.local/lib/python3.10/site-packages/botocore/client.py", line 565, in _api_call
    return self._make_api_call(operation_name, kwargs)
  File "/home/airflow/.local/lib/python3.10/site-packages/botocore/client.py", line 999, in _make_api_call
    http, parsed_response = self._make_request(
  File "/home/airflow/.local/lib/python3.10/site-packages/botocore/client.py", line 1023, in _make_request
    return self._endpoint.make_request(operation_model, request_dict)
  File "/home/airflow/.local/lib/python3.10/site-packages/botocore/endpoint.py", line 119, in make_request
    return self._send_request(request_dict, operation_model)
  File "/home/airflow/.local/lib/python3.10/site-packages/botocore/endpoint.py", line 200, in _send_request
    while self._needs_retry(
  File "/home/airflow/.local/lib/python3.10/site-packages/botocore/endpoint.py", line 352, in _needs_retry
    responses = self._event_emitter.emit(
  File "/home/airflow/.local/lib/python3.10/site-packages/botocore/hooks.py", line 412, in emit
    return self._emitter.emit(aliased_event_name, **kwargs)
  File "/home/airflow/.local/lib/python3.10/site-packages/botocore/hooks.py", line 256, in emit
    return self._emit(event_name, kwargs)
  File "/home/airflow/.local/lib/python3.10/site-packages/botocore/hooks.py", line 239, in _emit
    response = handler(**kwargs)
  File "/home/airflow/.local/lib/python3.10/site-packages/botocore/retryhandler.py", line 207, in __call__
    if self._checker(**checker_kwargs):
  File "/home/airflow/.local/lib/python3.10/site-packages/botocore/retryhandler.py", line 284, in __call__
    should_retry = self._should_retry(
  File "/home/airflow/.local/lib/python3.10/site-packages/botocore/retryhandler.py", line 320, in _should_retry
    return self._checker(attempt_number, response, caught_exception)
  File "/home/airflow/.local/lib/python3.10/site-packages/botocore/retryhandler.py", line 363, in __call__
    checker_response = checker(
  File "/home/airflow/.local/lib/python3.10/site-packages/botocore/retryhandler.py", line 247, in __call__
    return self._check_caught_exception(
  File "/home/airflow/.local/lib/python3.10/site-packages/botocore/retryhandler.py", line 416, in _check_caught_exception
    raise caught_exception
  File "/home/airflow/.local/lib/python3.10/site-packages/botocore/endpoint.py", line 279, in _do_get_response
    http_response = self._send(request)
  File "/home/airflow/.local/lib/python3.10/site-packages/botocore/endpoint.py", line 375, in _send
    return self.http_session.send(request)
  File "/home/airflow/.local/lib/python3.10/site-packages/botocore/httpsession.py", line 493, in send
    raise EndpointConnectionError(endpoint_url=request.url, error=e)
botocore.exceptions.EndpointConnectionError: Could not connect to the endpoint URL: "http://3.37.147.123:9000/user-action-log"
[2025-05-23T02:04:57.322+0000] {local_task_job_runner.py:266} INFO - Task exited with return code 1
[2025-05-23T02:04:57.330+0000] {taskinstance.py:3900} INFO - 0 downstream tasks scheduled from follow-on schedule check
[2025-05-23T02:04:57.331+0000] {local_task_job_runner.py:245} INFO - ::endgroup::
