[2025-05-19T07:18:08.594+0000] {local_task_job_runner.py:123} INFO - ::group::Pre task execution logs
[2025-05-19T07:18:08.679+0000] {taskinstance.py:2612} INFO - Dependencies all met for dep_context=non-requeueable deps ti=<TaskInstance: csv_to_parquet.csv_to_parquet scheduled__2025-05-19T07:05:00+00:00 [queued]>
[2025-05-19T07:18:08.683+0000] {taskinstance.py:2612} INFO - Dependencies all met for dep_context=requeueable deps ti=<TaskInstance: csv_to_parquet.csv_to_parquet scheduled__2025-05-19T07:05:00+00:00 [queued]>
[2025-05-19T07:18:08.683+0000] {taskinstance.py:2865} INFO - Starting attempt 2 of 2
[2025-05-19T07:18:08.688+0000] {taskinstance.py:2888} INFO - Executing <Task(SSHOperator): csv_to_parquet> on 2025-05-19 07:05:00+00:00
[2025-05-19T07:18:08.690+0000] {standard_task_runner.py:72} INFO - Started process 973 to run task
[2025-05-19T07:18:08.692+0000] {standard_task_runner.py:104} INFO - Running: ['***', 'tasks', 'run', 'csv_to_parquet', 'csv_to_parquet', 'scheduled__2025-05-19T07:05:00+00:00', '--job-id', '33', '--raw', '--subdir', 'DAGS_FOLDER/log_to_csv.py', '--cfg-path', '/tmp/tmpzg4gik2v']
[2025-05-19T07:18:08.693+0000] {standard_task_runner.py:105} INFO - Job 33: Subtask csv_to_parquet
[2025-05-19T07:18:08.717+0000] {task_command.py:467} INFO - Running <TaskInstance: csv_to_parquet.csv_to_parquet scheduled__2025-05-19T07:05:00+00:00 [running]> on host 8b6a4ce3396b
[2025-05-19T07:18:08.751+0000] {taskinstance.py:3131} INFO - Exporting env vars: AIRFLOW_CTX_DAG_OWNER='***' AIRFLOW_CTX_DAG_ID='csv_to_parquet' AIRFLOW_CTX_TASK_ID='csv_to_parquet' AIRFLOW_CTX_EXECUTION_DATE='2025-05-19T07:05:00+00:00' AIRFLOW_CTX_TRY_NUMBER='2' AIRFLOW_CTX_DAG_RUN_ID='scheduled__2025-05-19T07:05:00+00:00'
[2025-05-19T07:18:08.752+0000] {taskinstance.py:731} INFO - ::endgroup::
[2025-05-19T07:18:08.757+0000] {ssh.py:124} INFO - ssh_hook is not provided or invalid. Trying ssh_conn_id to create SSHHook.
[2025-05-19T07:18:08.761+0000] {base.py:84} INFO - Retrieving connection 'local_ssh'
[2025-05-19T07:18:08.762+0000] {ssh.py:309} WARNING - No Host Key Verification. This won't protect against Man-In-The-Middle attacks
[2025-05-19T07:18:08.763+0000] {ssh.py:351} INFO - Failed to connect. Sleeping before retry attempt 1
[2025-05-19T07:18:11.961+0000] {ssh.py:351} INFO - Failed to connect. Sleeping before retry attempt 2
[2025-05-19T07:18:16.849+0000] {taskinstance.py:3310} ERROR - Task failed with exception
Traceback (most recent call last):
  File "/home/airflow/.local/lib/python3.10/site-packages/airflow/models/taskinstance.py", line 762, in _execute_task
    result = _execute_callable(context=context, **execute_callable_kwargs)
  File "/home/airflow/.local/lib/python3.10/site-packages/airflow/models/taskinstance.py", line 733, in _execute_callable
    return ExecutionCallableRunner(
  File "/home/airflow/.local/lib/python3.10/site-packages/airflow/utils/operator_helpers.py", line 252, in run
    return self.func(*args, **kwargs)
  File "/home/airflow/.local/lib/python3.10/site-packages/airflow/models/baseoperator.py", line 406, in wrapper
    return func(self, *args, **kwargs)
  File "/home/airflow/.local/lib/python3.10/site-packages/airflow/providers/ssh/operators/ssh.py", line 189, in execute
    with self.get_ssh_client() as ssh_client:
  File "/home/airflow/.local/lib/python3.10/site-packages/airflow/providers/ssh/operators/ssh.py", line 151, in get_ssh_client
    return self.hook.get_conn()
  File "/home/airflow/.local/lib/python3.10/site-packages/airflow/providers/ssh/hooks/ssh.py", line 355, in get_conn
    for attempt in Retrying(
  File "/home/airflow/.local/lib/python3.10/site-packages/tenacity/__init__.py", line 443, in __iter__
    do = self.iter(retry_state=retry_state)
  File "/home/airflow/.local/lib/python3.10/site-packages/tenacity/__init__.py", line 376, in iter
    result = action(retry_state)
  File "/home/airflow/.local/lib/python3.10/site-packages/tenacity/__init__.py", line 418, in exc_check
    raise retry_exc.reraise()
  File "/home/airflow/.local/lib/python3.10/site-packages/tenacity/__init__.py", line 185, in reraise
    raise self.last_attempt.result()
  File "/usr/local/lib/python3.10/concurrent/futures/_base.py", line 451, in result
    return self.__get_result()
  File "/usr/local/lib/python3.10/concurrent/futures/_base.py", line 403, in __get_result
    raise self._exception
  File "/home/airflow/.local/lib/python3.10/site-packages/airflow/providers/ssh/hooks/ssh.py", line 362, in get_conn
    client.connect(**connect_kwargs)
  File "/home/airflow/.local/lib/python3.10/site-packages/paramiko/client.py", line 386, in connect
    sock.connect(addr)
OSError: [Errno 101] Network is unreachable
[2025-05-19T07:18:16.858+0000] {taskinstance.py:1225} INFO - Marking task as FAILED. dag_id=csv_to_parquet, task_id=csv_to_parquet, run_id=scheduled__2025-05-19T07:05:00+00:00, execution_date=20250519T070500, start_date=20250519T071808, end_date=20250519T071816
[2025-05-19T07:18:16.867+0000] {taskinstance.py:340} INFO - ::group::Post task execution logs
[2025-05-19T07:18:16.868+0000] {standard_task_runner.py:124} ERROR - Failed to execute job 33 for task csv_to_parquet ([Errno 101] Network is unreachable; 973)
Traceback (most recent call last):
  File "/home/airflow/.local/lib/python3.10/site-packages/airflow/task/task_runner/standard_task_runner.py", line 117, in _start_by_fork
    ret = args.func(args, dag=self.dag)
  File "/home/airflow/.local/lib/python3.10/site-packages/airflow/cli/cli_config.py", line 49, in command
    return func(*args, **kwargs)
  File "/home/airflow/.local/lib/python3.10/site-packages/airflow/utils/cli.py", line 115, in wrapper
    return f(*args, **kwargs)
  File "/home/airflow/.local/lib/python3.10/site-packages/airflow/cli/commands/task_command.py", line 483, in task_run
    task_return_code = _run_task_by_selected_method(args, _dag, ti)
  File "/home/airflow/.local/lib/python3.10/site-packages/airflow/cli/commands/task_command.py", line 256, in _run_task_by_selected_method
    return _run_raw_task(args, ti)
  File "/home/airflow/.local/lib/python3.10/site-packages/airflow/cli/commands/task_command.py", line 341, in _run_raw_task
    return ti._run_raw_task(
  File "/home/airflow/.local/lib/python3.10/site-packages/airflow/utils/session.py", line 97, in wrapper
    return func(*args, session=session, **kwargs)
  File "/home/airflow/.local/lib/python3.10/site-packages/airflow/models/taskinstance.py", line 3004, in _run_raw_task
    return _run_raw_task(
  File "/home/airflow/.local/lib/python3.10/site-packages/airflow/models/taskinstance.py", line 273, in _run_raw_task
    TaskInstance._execute_task_with_callbacks(
  File "/home/airflow/.local/lib/python3.10/site-packages/airflow/models/taskinstance.py", line 3158, in _execute_task_with_callbacks
    result = self._execute_task(context, task_orig)
  File "/home/airflow/.local/lib/python3.10/site-packages/airflow/models/taskinstance.py", line 3182, in _execute_task
    return _execute_task(self, context, task_orig)
  File "/home/airflow/.local/lib/python3.10/site-packages/airflow/models/taskinstance.py", line 762, in _execute_task
    result = _execute_callable(context=context, **execute_callable_kwargs)
  File "/home/airflow/.local/lib/python3.10/site-packages/airflow/models/taskinstance.py", line 733, in _execute_callable
    return ExecutionCallableRunner(
  File "/home/airflow/.local/lib/python3.10/site-packages/airflow/utils/operator_helpers.py", line 252, in run
    return self.func(*args, **kwargs)
  File "/home/airflow/.local/lib/python3.10/site-packages/airflow/models/baseoperator.py", line 406, in wrapper
    return func(self, *args, **kwargs)
  File "/home/airflow/.local/lib/python3.10/site-packages/airflow/providers/ssh/operators/ssh.py", line 189, in execute
    with self.get_ssh_client() as ssh_client:
  File "/home/airflow/.local/lib/python3.10/site-packages/airflow/providers/ssh/operators/ssh.py", line 151, in get_ssh_client
    return self.hook.get_conn()
  File "/home/airflow/.local/lib/python3.10/site-packages/airflow/providers/ssh/hooks/ssh.py", line 355, in get_conn
    for attempt in Retrying(
  File "/home/airflow/.local/lib/python3.10/site-packages/tenacity/__init__.py", line 443, in __iter__
    do = self.iter(retry_state=retry_state)
  File "/home/airflow/.local/lib/python3.10/site-packages/tenacity/__init__.py", line 376, in iter
    result = action(retry_state)
  File "/home/airflow/.local/lib/python3.10/site-packages/tenacity/__init__.py", line 418, in exc_check
    raise retry_exc.reraise()
  File "/home/airflow/.local/lib/python3.10/site-packages/tenacity/__init__.py", line 185, in reraise
    raise self.last_attempt.result()
  File "/usr/local/lib/python3.10/concurrent/futures/_base.py", line 451, in result
    return self.__get_result()
  File "/usr/local/lib/python3.10/concurrent/futures/_base.py", line 403, in __get_result
    raise self._exception
  File "/home/airflow/.local/lib/python3.10/site-packages/airflow/providers/ssh/hooks/ssh.py", line 362, in get_conn
    client.connect(**connect_kwargs)
  File "/home/airflow/.local/lib/python3.10/site-packages/paramiko/client.py", line 386, in connect
    sock.connect(addr)
OSError: [Errno 101] Network is unreachable
[2025-05-19T07:18:16.913+0000] {local_task_job_runner.py:266} INFO - Task exited with return code 1
[2025-05-19T07:18:16.926+0000] {taskinstance.py:3900} INFO - 0 downstream tasks scheduled from follow-on schedule check
[2025-05-19T07:18:16.927+0000] {local_task_job_runner.py:245} INFO - ::endgroup::
