[2025-05-23T02:10:03.910+0000] {local_task_job_runner.py:123} INFO - ::group::Pre task execution logs
[2025-05-23T02:10:03.915+0000] {taskinstance.py:2612} INFO - Dependencies all met for dep_context=non-requeueable deps ti=<TaskInstance: kafka_to_minio_to_spark.check_minio_file scheduled__2025-05-22T16:00:00+00:00 [queued]>
[2025-05-23T02:10:03.918+0000] {taskinstance.py:2612} INFO - Dependencies all met for dep_context=requeueable deps ti=<TaskInstance: kafka_to_minio_to_spark.check_minio_file scheduled__2025-05-22T16:00:00+00:00 [queued]>
[2025-05-23T02:10:03.918+0000] {taskinstance.py:2865} INFO - Starting attempt 6 of 8
[2025-05-23T02:10:03.922+0000] {taskinstance.py:2888} INFO - Executing <Task(S3KeySensor): check_minio_file> on 2025-05-22 16:00:00+00:00
[2025-05-23T02:10:03.924+0000] {standard_task_runner.py:72} INFO - Started process 588 to run task
[2025-05-23T02:10:03.926+0000] {standard_task_runner.py:104} INFO - Running: ['***', 'tasks', 'run', 'kafka_to_minio_to_spark', 'check_minio_file', 'scheduled__2025-05-22T16:00:00+00:00', '--job-id', '355', '--raw', '--subdir', 'DAGS_FOLDER/testlog_ml.py', '--cfg-path', '/tmp/tmp6u1qh24x']
[2025-05-23T02:10:03.926+0000] {standard_task_runner.py:105} INFO - Job 355: Subtask check_minio_file
[2025-05-23T02:10:03.944+0000] {task_command.py:467} INFO - Running <TaskInstance: kafka_to_minio_to_spark.check_minio_file scheduled__2025-05-22T16:00:00+00:00 [running]> on host 3e84bbc47e1b
[2025-05-23T02:10:03.970+0000] {taskinstance.py:3131} INFO - Exporting env vars: AIRFLOW_CTX_DAG_OWNER='***' AIRFLOW_CTX_DAG_ID='kafka_to_minio_to_spark' AIRFLOW_CTX_TASK_ID='check_minio_file' AIRFLOW_CTX_EXECUTION_DATE='2025-05-22T16:00:00+00:00' AIRFLOW_CTX_TRY_NUMBER='6' AIRFLOW_CTX_DAG_RUN_ID='scheduled__2025-05-22T16:00:00+00:00'
[2025-05-23T02:10:03.970+0000] {taskinstance.py:731} INFO - ::endgroup::
[2025-05-23T02:10:03.975+0000] {baseoperator.py:405} WARNING - S3KeySensor.execute cannot be called outside TaskInstance!
[2025-05-23T02:10:03.976+0000] {s3.py:118} INFO - Poking for key : s3://user-log-ml/2025-05-23_*.csv
[2025-05-23T02:10:03.980+0000] {base.py:84} INFO - Retrieving connection 'minio'
[2025-05-23T02:10:03.980+0000] {connection_wrapper.py:388} INFO - AWS Connection (conn_id='minio', conn_type='aws') credentials retrieved from login and password.
[2025-05-23T02:10:09.241+0000] {s3.py:118} INFO - Poking for key : s3://user-log-ml/2025-05-23_*.csv
[2025-05-23T02:10:14.266+0000] {s3.py:118} INFO - Poking for key : s3://user-log-ml/2025-05-23_*.csv
[2025-05-23T02:10:19.024+0000] {local_task_job_runner.py:346} WARNING - State of this instance has been externally set to restarting. Terminating instance.
[2025-05-23T02:10:19.026+0000] {local_task_job_runner.py:245} INFO - ::endgroup::
[2025-05-23T02:10:19.028+0000] {process_utils.py:132} INFO - Sending 15 to group 588. PIDs of all processes in the group: [588]
[2025-05-23T02:10:19.028+0000] {process_utils.py:87} INFO - Sending the signal 15 to group 588
[2025-05-23T02:10:19.029+0000] {taskinstance.py:3092} ERROR - Received SIGTERM. Terminating subprocesses.
[2025-05-23T02:10:19.041+0000] {taskinstance.py:3310} ERROR - Task failed with exception
Traceback (most recent call last):
  File "/home/airflow/.local/lib/python3.10/site-packages/airflow/models/taskinstance.py", line 762, in _execute_task
    result = _execute_callable(context=context, **execute_callable_kwargs)
  File "/home/airflow/.local/lib/python3.10/site-packages/airflow/models/taskinstance.py", line 733, in _execute_callable
    return ExecutionCallableRunner(
  File "/home/airflow/.local/lib/python3.10/site-packages/airflow/utils/operator_helpers.py", line 252, in run
    return self.func(*args, **kwargs)
  File "/home/airflow/.local/lib/python3.10/site-packages/airflow/models/baseoperator.py", line 406, in wrapper
    return func(self, *args, **kwargs)
  File "/home/airflow/.local/lib/python3.10/site-packages/airflow/providers/amazon/aws/sensors/s3.py", line 189, in execute
    super().execute(context)
  File "/home/airflow/.local/lib/python3.10/site-packages/airflow/models/baseoperator.py", line 406, in wrapper
    return func(self, *args, **kwargs)
  File "/home/airflow/.local/lib/python3.10/site-packages/airflow/sensors/base.py", line 334, in execute
    time.sleep(self._get_next_poke_interval(started_at, run_duration, poke_count))
  File "/home/airflow/.local/lib/python3.10/site-packages/airflow/models/taskinstance.py", line 3094, in signal_handler
    raise AirflowTaskTerminated("Task received SIGTERM signal")
airflow.exceptions.AirflowTaskTerminated: Task received SIGTERM signal
[2025-05-23T02:10:19.044+0000] {taskinstance.py:1225} INFO - Marking task as UP_FOR_RETRY. dag_id=kafka_to_minio_to_spark, task_id=check_minio_file, run_id=scheduled__2025-05-22T16:00:00+00:00, execution_date=20250522T160000, start_date=20250523T021003, end_date=20250523T021019
[2025-05-23T02:10:19.053+0000] {taskinstance.py:340} INFO - ::group::Post task execution logs
[2025-05-23T02:10:19.064+0000] {process_utils.py:80} INFO - Process psutil.Process(pid=588, status='terminated', exitcode=2, started='02:10:03') (588) terminated with exit code 2
