[2025-05-23T01:59:52.863+0000] {local_task_job_runner.py:123} INFO - ::group::Pre task execution logs
[2025-05-23T01:59:52.869+0000] {taskinstance.py:2612} INFO - Dependencies all met for dep_context=non-requeueable deps ti=<TaskInstance: kafka_to_minio_to_spark.check_minio_file scheduled__2025-05-22T16:00:00+00:00 [queued]>
[2025-05-23T01:59:52.872+0000] {taskinstance.py:2612} INFO - Dependencies all met for dep_context=requeueable deps ti=<TaskInstance: kafka_to_minio_to_spark.check_minio_file scheduled__2025-05-22T16:00:00+00:00 [queued]>
[2025-05-23T01:59:52.872+0000] {taskinstance.py:2865} INFO - Starting attempt 5 of 7
[2025-05-23T01:59:52.877+0000] {taskinstance.py:2888} INFO - Executing <Task(S3KeySensor): check_minio_file> on 2025-05-22 16:00:00+00:00
[2025-05-23T01:59:52.880+0000] {standard_task_runner.py:72} INFO - Started process 441 to run task
[2025-05-23T01:59:52.882+0000] {standard_task_runner.py:104} INFO - Running: ['***', 'tasks', 'run', 'kafka_to_minio_to_spark', 'check_minio_file', 'scheduled__2025-05-22T16:00:00+00:00', '--job-id', '351', '--raw', '--subdir', 'DAGS_FOLDER/testlog_ml.py', '--cfg-path', '/tmp/tmp9_u9nlie']
[2025-05-23T01:59:52.882+0000] {standard_task_runner.py:105} INFO - Job 351: Subtask check_minio_file
[2025-05-23T01:59:52.904+0000] {task_command.py:467} INFO - Running <TaskInstance: kafka_to_minio_to_spark.check_minio_file scheduled__2025-05-22T16:00:00+00:00 [running]> on host 3e84bbc47e1b
[2025-05-23T01:59:52.932+0000] {taskinstance.py:3131} INFO - Exporting env vars: AIRFLOW_CTX_DAG_OWNER='***' AIRFLOW_CTX_DAG_ID='kafka_to_minio_to_spark' AIRFLOW_CTX_TASK_ID='check_minio_file' AIRFLOW_CTX_EXECUTION_DATE='2025-05-22T16:00:00+00:00' AIRFLOW_CTX_TRY_NUMBER='5' AIRFLOW_CTX_DAG_RUN_ID='scheduled__2025-05-22T16:00:00+00:00'
[2025-05-23T01:59:52.933+0000] {taskinstance.py:731} INFO - ::endgroup::
[2025-05-23T01:59:52.937+0000] {baseoperator.py:405} WARNING - S3KeySensor.execute cannot be called outside TaskInstance!
[2025-05-23T01:59:52.937+0000] {s3.py:118} INFO - Poking for key : s3://user-log-ml/2025-05-23_*.csv
[2025-05-23T01:59:52.942+0000] {base.py:84} INFO - Retrieving connection 'minio'
[2025-05-23T01:59:52.942+0000] {connection_wrapper.py:388} INFO - AWS Connection (conn_id='minio', conn_type='aws') credentials retrieved from login and password.
[2025-05-23T02:00:01.082+0000] {taskinstance.py:3310} ERROR - Task failed with exception
Traceback (most recent call last):
  File "/home/airflow/.local/lib/python3.10/site-packages/urllib3/connection.py", line 196, in _new_conn
    sock = connection.create_connection(
  File "/home/airflow/.local/lib/python3.10/site-packages/urllib3/util/connection.py", line 85, in create_connection
    raise err
  File "/home/airflow/.local/lib/python3.10/site-packages/urllib3/util/connection.py", line 73, in create_connection
    sock.connect(sa)
ConnectionRefusedError: [Errno 111] Connection refused

The above exception was the direct cause of the following exception:

Traceback (most recent call last):
  File "/home/airflow/.local/lib/python3.10/site-packages/botocore/httpsession.py", line 464, in send
    urllib_response = conn.urlopen(
  File "/home/airflow/.local/lib/python3.10/site-packages/urllib3/connectionpool.py", line 843, in urlopen
    retries = retries.increment(
  File "/home/airflow/.local/lib/python3.10/site-packages/urllib3/util/retry.py", line 449, in increment
    raise reraise(type(error), error, _stacktrace)
  File "/home/airflow/.local/lib/python3.10/site-packages/urllib3/util/util.py", line 39, in reraise
    raise value
  File "/home/airflow/.local/lib/python3.10/site-packages/urllib3/connectionpool.py", line 789, in urlopen
    response = self._make_request(
  File "/home/airflow/.local/lib/python3.10/site-packages/urllib3/connectionpool.py", line 495, in _make_request
    conn.request(
  File "/home/airflow/.local/lib/python3.10/site-packages/botocore/awsrequest.py", line 96, in request
    rval = super().request(method, url, body, headers, *args, **kwargs)
  File "/home/airflow/.local/lib/python3.10/site-packages/urllib3/connection.py", line 398, in request
    self.endheaders()
  File "/usr/local/lib/python3.10/http/client.py", line 1278, in endheaders
    self._send_output(message_body, encode_chunked=encode_chunked)
  File "/home/airflow/.local/lib/python3.10/site-packages/botocore/awsrequest.py", line 123, in _send_output
    self.send(msg)
  File "/home/airflow/.local/lib/python3.10/site-packages/botocore/awsrequest.py", line 223, in send
    return super().send(str)
  File "/usr/local/lib/python3.10/http/client.py", line 976, in send
    self.connect()
  File "/home/airflow/.local/lib/python3.10/site-packages/urllib3/connection.py", line 236, in connect
    self.sock = self._new_conn()
  File "/home/airflow/.local/lib/python3.10/site-packages/urllib3/connection.py", line 211, in _new_conn
    raise NewConnectionError(
urllib3.exceptions.NewConnectionError: <botocore.awsrequest.AWSHTTPConnection object at 0xffff65c43d00>: Failed to establish a new connection: [Errno 111] Connection refused

During handling of the above exception, another exception occurred:

Traceback (most recent call last):
  File "/home/airflow/.local/lib/python3.10/site-packages/airflow/models/taskinstance.py", line 762, in _execute_task
    result = _execute_callable(context=context, **execute_callable_kwargs)
  File "/home/airflow/.local/lib/python3.10/site-packages/airflow/models/taskinstance.py", line 733, in _execute_callable
    return ExecutionCallableRunner(
  File "/home/airflow/.local/lib/python3.10/site-packages/airflow/utils/operator_helpers.py", line 252, in run
    return self.func(*args, **kwargs)
  File "/home/airflow/.local/lib/python3.10/site-packages/airflow/models/baseoperator.py", line 406, in wrapper
    return func(self, *args, **kwargs)
  File "/home/airflow/.local/lib/python3.10/site-packages/airflow/providers/amazon/aws/sensors/s3.py", line 189, in execute
    super().execute(context)
  File "/home/airflow/.local/lib/python3.10/site-packages/airflow/models/baseoperator.py", line 406, in wrapper
    return func(self, *args, **kwargs)
  File "/home/airflow/.local/lib/python3.10/site-packages/airflow/sensors/base.py", line 306, in execute
    raise e
  File "/home/airflow/.local/lib/python3.10/site-packages/airflow/sensors/base.py", line 286, in execute
    poke_return = self.poke(context)
  File "/home/airflow/.local/lib/python3.10/site-packages/airflow/providers/amazon/aws/sensors/s3.py", line 182, in poke
    return self._check_key(self.bucket_key, context=context)
  File "/home/airflow/.local/lib/python3.10/site-packages/airflow/providers/amazon/aws/sensors/s3.py", line 128, in _check_key
    keys = self.hook.get_file_metadata(prefix, bucket_name)
  File "/home/airflow/.local/lib/python3.10/site-packages/airflow/providers/amazon/aws/hooks/s3.py", line 132, in wrapper
    return func(*bound_args.args, **bound_args.kwargs)
  File "/home/airflow/.local/lib/python3.10/site-packages/airflow/providers/amazon/aws/hooks/s3.py", line 900, in get_file_metadata
    for page in response:
  File "/home/airflow/.local/lib/python3.10/site-packages/botocore/paginate.py", line 269, in __iter__
    response = self._make_request(current_kwargs)
  File "/home/airflow/.local/lib/python3.10/site-packages/botocore/paginate.py", line 357, in _make_request
    return self._method(**current_kwargs)
  File "/home/airflow/.local/lib/python3.10/site-packages/botocore/client.py", line 565, in _api_call
    return self._make_api_call(operation_name, kwargs)
  File "/home/airflow/.local/lib/python3.10/site-packages/botocore/client.py", line 999, in _make_api_call
    http, parsed_response = self._make_request(
  File "/home/airflow/.local/lib/python3.10/site-packages/botocore/client.py", line 1023, in _make_request
    return self._endpoint.make_request(operation_model, request_dict)
  File "/home/airflow/.local/lib/python3.10/site-packages/botocore/endpoint.py", line 119, in make_request
    return self._send_request(request_dict, operation_model)
  File "/home/airflow/.local/lib/python3.10/site-packages/botocore/endpoint.py", line 200, in _send_request
    while self._needs_retry(
  File "/home/airflow/.local/lib/python3.10/site-packages/botocore/endpoint.py", line 352, in _needs_retry
    responses = self._event_emitter.emit(
  File "/home/airflow/.local/lib/python3.10/site-packages/botocore/hooks.py", line 412, in emit
    return self._emitter.emit(aliased_event_name, **kwargs)
  File "/home/airflow/.local/lib/python3.10/site-packages/botocore/hooks.py", line 256, in emit
    return self._emit(event_name, kwargs)
  File "/home/airflow/.local/lib/python3.10/site-packages/botocore/hooks.py", line 239, in _emit
    response = handler(**kwargs)
  File "/home/airflow/.local/lib/python3.10/site-packages/botocore/retryhandler.py", line 207, in __call__
    if self._checker(**checker_kwargs):
  File "/home/airflow/.local/lib/python3.10/site-packages/botocore/retryhandler.py", line 284, in __call__
    should_retry = self._should_retry(
  File "/home/airflow/.local/lib/python3.10/site-packages/botocore/retryhandler.py", line 320, in _should_retry
    return self._checker(attempt_number, response, caught_exception)
  File "/home/airflow/.local/lib/python3.10/site-packages/botocore/retryhandler.py", line 363, in __call__
    checker_response = checker(
  File "/home/airflow/.local/lib/python3.10/site-packages/botocore/retryhandler.py", line 247, in __call__
    return self._check_caught_exception(
  File "/home/airflow/.local/lib/python3.10/site-packages/botocore/retryhandler.py", line 416, in _check_caught_exception
    raise caught_exception
  File "/home/airflow/.local/lib/python3.10/site-packages/botocore/endpoint.py", line 279, in _do_get_response
    http_response = self._send(request)
  File "/home/airflow/.local/lib/python3.10/site-packages/botocore/endpoint.py", line 375, in _send
    return self.http_session.send(request)
  File "/home/airflow/.local/lib/python3.10/site-packages/botocore/httpsession.py", line 493, in send
    raise EndpointConnectionError(endpoint_url=request.url, error=e)
botocore.exceptions.EndpointConnectionError: Could not connect to the endpoint URL: "http://3.37.147.123:9000/user-log-ml?list-type=2&prefix=2025-05-23_&encoding-type=url"
[2025-05-23T02:00:01.108+0000] {taskinstance.py:1225} INFO - Marking task as UP_FOR_RETRY. dag_id=kafka_to_minio_to_spark, task_id=check_minio_file, run_id=scheduled__2025-05-22T16:00:00+00:00, execution_date=20250522T160000, start_date=20250523T015952, end_date=20250523T020001
[2025-05-23T02:00:01.120+0000] {taskinstance.py:340} INFO - ::group::Post task execution logs
[2025-05-23T02:00:01.121+0000] {standard_task_runner.py:124} ERROR - Failed to execute job 351 for task check_minio_file (Could not connect to the endpoint URL: "http://3.37.147.123:9000/user-log-ml?list-type=2&prefix=2025-05-23_&encoding-type=url"; 441)
Traceback (most recent call last):
  File "/home/airflow/.local/lib/python3.10/site-packages/urllib3/connection.py", line 196, in _new_conn
    sock = connection.create_connection(
  File "/home/airflow/.local/lib/python3.10/site-packages/urllib3/util/connection.py", line 85, in create_connection
    raise err
  File "/home/airflow/.local/lib/python3.10/site-packages/urllib3/util/connection.py", line 73, in create_connection
    sock.connect(sa)
ConnectionRefusedError: [Errno 111] Connection refused

The above exception was the direct cause of the following exception:

Traceback (most recent call last):
  File "/home/airflow/.local/lib/python3.10/site-packages/botocore/httpsession.py", line 464, in send
    urllib_response = conn.urlopen(
  File "/home/airflow/.local/lib/python3.10/site-packages/urllib3/connectionpool.py", line 843, in urlopen
    retries = retries.increment(
  File "/home/airflow/.local/lib/python3.10/site-packages/urllib3/util/retry.py", line 449, in increment
    raise reraise(type(error), error, _stacktrace)
  File "/home/airflow/.local/lib/python3.10/site-packages/urllib3/util/util.py", line 39, in reraise
    raise value
  File "/home/airflow/.local/lib/python3.10/site-packages/urllib3/connectionpool.py", line 789, in urlopen
    response = self._make_request(
  File "/home/airflow/.local/lib/python3.10/site-packages/urllib3/connectionpool.py", line 495, in _make_request
    conn.request(
  File "/home/airflow/.local/lib/python3.10/site-packages/botocore/awsrequest.py", line 96, in request
    rval = super().request(method, url, body, headers, *args, **kwargs)
  File "/home/airflow/.local/lib/python3.10/site-packages/urllib3/connection.py", line 398, in request
    self.endheaders()
  File "/usr/local/lib/python3.10/http/client.py", line 1278, in endheaders
    self._send_output(message_body, encode_chunked=encode_chunked)
  File "/home/airflow/.local/lib/python3.10/site-packages/botocore/awsrequest.py", line 123, in _send_output
    self.send(msg)
  File "/home/airflow/.local/lib/python3.10/site-packages/botocore/awsrequest.py", line 223, in send
    return super().send(str)
  File "/usr/local/lib/python3.10/http/client.py", line 976, in send
    self.connect()
  File "/home/airflow/.local/lib/python3.10/site-packages/urllib3/connection.py", line 236, in connect
    self.sock = self._new_conn()
  File "/home/airflow/.local/lib/python3.10/site-packages/urllib3/connection.py", line 211, in _new_conn
    raise NewConnectionError(
urllib3.exceptions.NewConnectionError: <botocore.awsrequest.AWSHTTPConnection object at 0xffff65c43d00>: Failed to establish a new connection: [Errno 111] Connection refused

During handling of the above exception, another exception occurred:

Traceback (most recent call last):
  File "/home/airflow/.local/lib/python3.10/site-packages/airflow/task/task_runner/standard_task_runner.py", line 117, in _start_by_fork
    ret = args.func(args, dag=self.dag)
  File "/home/airflow/.local/lib/python3.10/site-packages/airflow/cli/cli_config.py", line 49, in command
    return func(*args, **kwargs)
  File "/home/airflow/.local/lib/python3.10/site-packages/airflow/utils/cli.py", line 115, in wrapper
    return f(*args, **kwargs)
  File "/home/airflow/.local/lib/python3.10/site-packages/airflow/cli/commands/task_command.py", line 483, in task_run
    task_return_code = _run_task_by_selected_method(args, _dag, ti)
  File "/home/airflow/.local/lib/python3.10/site-packages/airflow/cli/commands/task_command.py", line 256, in _run_task_by_selected_method
    return _run_raw_task(args, ti)
  File "/home/airflow/.local/lib/python3.10/site-packages/airflow/cli/commands/task_command.py", line 341, in _run_raw_task
    return ti._run_raw_task(
  File "/home/airflow/.local/lib/python3.10/site-packages/airflow/utils/session.py", line 97, in wrapper
    return func(*args, session=session, **kwargs)
  File "/home/airflow/.local/lib/python3.10/site-packages/airflow/models/taskinstance.py", line 3004, in _run_raw_task
    return _run_raw_task(
  File "/home/airflow/.local/lib/python3.10/site-packages/airflow/models/taskinstance.py", line 273, in _run_raw_task
    TaskInstance._execute_task_with_callbacks(
  File "/home/airflow/.local/lib/python3.10/site-packages/airflow/models/taskinstance.py", line 3158, in _execute_task_with_callbacks
    result = self._execute_task(context, task_orig)
  File "/home/airflow/.local/lib/python3.10/site-packages/airflow/models/taskinstance.py", line 3182, in _execute_task
    return _execute_task(self, context, task_orig)
  File "/home/airflow/.local/lib/python3.10/site-packages/airflow/models/taskinstance.py", line 762, in _execute_task
    result = _execute_callable(context=context, **execute_callable_kwargs)
  File "/home/airflow/.local/lib/python3.10/site-packages/airflow/models/taskinstance.py", line 733, in _execute_callable
    return ExecutionCallableRunner(
  File "/home/airflow/.local/lib/python3.10/site-packages/airflow/utils/operator_helpers.py", line 252, in run
    return self.func(*args, **kwargs)
  File "/home/airflow/.local/lib/python3.10/site-packages/airflow/models/baseoperator.py", line 406, in wrapper
    return func(self, *args, **kwargs)
  File "/home/airflow/.local/lib/python3.10/site-packages/airflow/providers/amazon/aws/sensors/s3.py", line 189, in execute
    super().execute(context)
  File "/home/airflow/.local/lib/python3.10/site-packages/airflow/models/baseoperator.py", line 406, in wrapper
    return func(self, *args, **kwargs)
  File "/home/airflow/.local/lib/python3.10/site-packages/airflow/sensors/base.py", line 306, in execute
    raise e
  File "/home/airflow/.local/lib/python3.10/site-packages/airflow/sensors/base.py", line 286, in execute
    poke_return = self.poke(context)
  File "/home/airflow/.local/lib/python3.10/site-packages/airflow/providers/amazon/aws/sensors/s3.py", line 182, in poke
    return self._check_key(self.bucket_key, context=context)
  File "/home/airflow/.local/lib/python3.10/site-packages/airflow/providers/amazon/aws/sensors/s3.py", line 128, in _check_key
    keys = self.hook.get_file_metadata(prefix, bucket_name)
  File "/home/airflow/.local/lib/python3.10/site-packages/airflow/providers/amazon/aws/hooks/s3.py", line 132, in wrapper
    return func(*bound_args.args, **bound_args.kwargs)
  File "/home/airflow/.local/lib/python3.10/site-packages/airflow/providers/amazon/aws/hooks/s3.py", line 900, in get_file_metadata
    for page in response:
  File "/home/airflow/.local/lib/python3.10/site-packages/botocore/paginate.py", line 269, in __iter__
    response = self._make_request(current_kwargs)
  File "/home/airflow/.local/lib/python3.10/site-packages/botocore/paginate.py", line 357, in _make_request
    return self._method(**current_kwargs)
  File "/home/airflow/.local/lib/python3.10/site-packages/botocore/client.py", line 565, in _api_call
    return self._make_api_call(operation_name, kwargs)
  File "/home/airflow/.local/lib/python3.10/site-packages/botocore/client.py", line 999, in _make_api_call
    http, parsed_response = self._make_request(
  File "/home/airflow/.local/lib/python3.10/site-packages/botocore/client.py", line 1023, in _make_request
    return self._endpoint.make_request(operation_model, request_dict)
  File "/home/airflow/.local/lib/python3.10/site-packages/botocore/endpoint.py", line 119, in make_request
    return self._send_request(request_dict, operation_model)
  File "/home/airflow/.local/lib/python3.10/site-packages/botocore/endpoint.py", line 200, in _send_request
    while self._needs_retry(
  File "/home/airflow/.local/lib/python3.10/site-packages/botocore/endpoint.py", line 352, in _needs_retry
    responses = self._event_emitter.emit(
  File "/home/airflow/.local/lib/python3.10/site-packages/botocore/hooks.py", line 412, in emit
    return self._emitter.emit(aliased_event_name, **kwargs)
  File "/home/airflow/.local/lib/python3.10/site-packages/botocore/hooks.py", line 256, in emit
    return self._emit(event_name, kwargs)
  File "/home/airflow/.local/lib/python3.10/site-packages/botocore/hooks.py", line 239, in _emit
    response = handler(**kwargs)
  File "/home/airflow/.local/lib/python3.10/site-packages/botocore/retryhandler.py", line 207, in __call__
    if self._checker(**checker_kwargs):
  File "/home/airflow/.local/lib/python3.10/site-packages/botocore/retryhandler.py", line 284, in __call__
    should_retry = self._should_retry(
  File "/home/airflow/.local/lib/python3.10/site-packages/botocore/retryhandler.py", line 320, in _should_retry
    return self._checker(attempt_number, response, caught_exception)
  File "/home/airflow/.local/lib/python3.10/site-packages/botocore/retryhandler.py", line 363, in __call__
    checker_response = checker(
  File "/home/airflow/.local/lib/python3.10/site-packages/botocore/retryhandler.py", line 247, in __call__
    return self._check_caught_exception(
  File "/home/airflow/.local/lib/python3.10/site-packages/botocore/retryhandler.py", line 416, in _check_caught_exception
    raise caught_exception
  File "/home/airflow/.local/lib/python3.10/site-packages/botocore/endpoint.py", line 279, in _do_get_response
    http_response = self._send(request)
  File "/home/airflow/.local/lib/python3.10/site-packages/botocore/endpoint.py", line 375, in _send
    return self.http_session.send(request)
  File "/home/airflow/.local/lib/python3.10/site-packages/botocore/httpsession.py", line 493, in send
    raise EndpointConnectionError(endpoint_url=request.url, error=e)
botocore.exceptions.EndpointConnectionError: Could not connect to the endpoint URL: "http://3.37.147.123:9000/user-log-ml?list-type=2&prefix=2025-05-23_&encoding-type=url"
[2025-05-23T02:00:01.150+0000] {local_task_job_runner.py:266} INFO - Task exited with return code 1
[2025-05-23T02:00:01.162+0000] {taskinstance.py:3900} INFO - 0 downstream tasks scheduled from follow-on schedule check
[2025-05-23T02:00:01.163+0000] {local_task_job_runner.py:245} INFO - ::endgroup::
