[2025-05-21T13:32:24.757+0000] {local_task_job_runner.py:123} INFO - ::group::Pre task execution logs
[2025-05-21T13:32:24.762+0000] {taskinstance.py:2612} INFO - Dependencies all met for dep_context=non-requeueable deps ti=<TaskInstance: kafka_to_minio_to_spark.kafka_consumer scheduled__2025-05-20T16:00:00+00:00 [queued]>
[2025-05-21T13:32:24.764+0000] {taskinstance.py:2612} INFO - Dependencies all met for dep_context=requeueable deps ti=<TaskInstance: kafka_to_minio_to_spark.kafka_consumer scheduled__2025-05-20T16:00:00+00:00 [queued]>
[2025-05-21T13:32:24.765+0000] {taskinstance.py:2865} INFO - Starting attempt 2 of 3
[2025-05-21T13:32:24.769+0000] {taskinstance.py:2888} INFO - Executing <Task(PythonOperator): kafka_consumer> on 2025-05-20 16:00:00+00:00
[2025-05-21T13:32:24.771+0000] {standard_task_runner.py:72} INFO - Started process 500 to run task
[2025-05-21T13:32:24.772+0000] {standard_task_runner.py:104} INFO - Running: ['***', 'tasks', 'run', 'kafka_to_minio_to_spark', 'kafka_consumer', 'scheduled__2025-05-20T16:00:00+00:00', '--job-id', '144', '--raw', '--subdir', 'DAGS_FOLDER/testlog_ml.py', '--cfg-path', '/tmp/tmp92brw5t2']
[2025-05-21T13:32:24.773+0000] {standard_task_runner.py:105} INFO - Job 144: Subtask kafka_consumer
[2025-05-21T13:32:24.791+0000] {task_command.py:467} INFO - Running <TaskInstance: kafka_to_minio_to_spark.kafka_consumer scheduled__2025-05-20T16:00:00+00:00 [running]> on host 87ceaf0fa525
[2025-05-21T13:32:24.821+0000] {taskinstance.py:3131} INFO - Exporting env vars: AIRFLOW_CTX_DAG_OWNER='***' AIRFLOW_CTX_DAG_ID='kafka_to_minio_to_spark' AIRFLOW_CTX_TASK_ID='kafka_consumer' AIRFLOW_CTX_EXECUTION_DATE='2025-05-20T16:00:00+00:00' AIRFLOW_CTX_TRY_NUMBER='2' AIRFLOW_CTX_DAG_RUN_ID='scheduled__2025-05-20T16:00:00+00:00'
[2025-05-21T13:32:24.822+0000] {taskinstance.py:731} INFO - ::endgroup::
[2025-05-21T13:32:24.829+0000] {conn.py:380} INFO - <BrokerConnection node_id=bootstrap-0 host=host.docker.internal:9092 <connecting> [IPv4 ('192.168.65.254', 9092)]>: connecting to host.docker.internal:9092 [('192.168.65.254', 9092) IPv4]
[2025-05-21T13:32:24.830+0000] {conn.py:1205} INFO - Probing node bootstrap-0 broker version
[2025-05-21T13:32:24.830+0000] {conn.py:418} ERROR - Connect attempt to <BrokerConnection node_id=bootstrap-0 host=host.docker.internal:9092 <connecting> [IPv4 ('192.168.65.254', 9092)]> returned error 111. Disconnecting.
[2025-05-21T13:32:24.831+0000] {conn.py:919} INFO - <BrokerConnection node_id=bootstrap-0 host=host.docker.internal:9092 <connecting> [IPv4 ('192.168.65.254', 9092)]>: Closing connection. KafkaConnectionError: 111 ECONNREFUSED
[2025-05-21T13:32:24.877+0000] {conn.py:380} INFO - <BrokerConnection node_id=bootstrap-0 host=host.docker.internal:9092 <connecting> [IPv4 ('192.168.65.254', 9092)]>: connecting to host.docker.internal:9092 [('192.168.65.254', 9092) IPv4]
[2025-05-21T13:32:24.877+0000] {conn.py:418} ERROR - Connect attempt to <BrokerConnection node_id=bootstrap-0 host=host.docker.internal:9092 <connecting> [IPv4 ('192.168.65.254', 9092)]> returned error 111. Disconnecting.
[2025-05-21T13:32:24.878+0000] {conn.py:919} INFO - <BrokerConnection node_id=bootstrap-0 host=host.docker.internal:9092 <connecting> [IPv4 ('192.168.65.254', 9092)]>: Closing connection. KafkaConnectionError: 111 ECONNREFUSED
[2025-05-21T13:32:24.927+0000] {conn.py:380} INFO - <BrokerConnection node_id=bootstrap-0 host=host.docker.internal:9092 <connecting> [IPv6 ('fdc4:f303:9324::254', 9092, 0, 0)]>: connecting to host.docker.internal:9092 [('fdc4:f303:9324::254', 9092, 0, 0) IPv6]
[2025-05-21T13:32:24.928+0000] {conn.py:418} ERROR - Connect attempt to <BrokerConnection node_id=bootstrap-0 host=host.docker.internal:9092 <connecting> [IPv6 ('fdc4:f303:9324::254', 9092, 0, 0)]> returned error 101. Disconnecting.
[2025-05-21T13:32:24.928+0000] {conn.py:919} INFO - <BrokerConnection node_id=bootstrap-0 host=host.docker.internal:9092 <connecting> [IPv6 ('fdc4:f303:9324::254', 9092, 0, 0)]>: Closing connection. KafkaConnectionError: 101 ENETUNREACH
[2025-05-21T13:32:24.928+0000] {logging_mixin.py:190} INFO - ‚ùå DAG failed due to : NoBrokersAvailable
[2025-05-21T13:32:24.929+0000] {taskinstance.py:3310} ERROR - Task failed with exception
Traceback (most recent call last):
  File "/opt/airflow/dags/testlog_ml.py", line 146, in kafka_consumer
    raise e
  File "/opt/airflow/dags/testlog_ml.py", line 82, in kafka_consumer
    consumer = KafkaConsumer(
  File "/home/airflow/.local/lib/python3.10/site-packages/kafka/consumer/group.py", line 356, in __init__
    self._client = KafkaClient(metrics=self._metrics, **self.config)
  File "/home/airflow/.local/lib/python3.10/site-packages/kafka/client_async.py", line 244, in __init__
    self.config['api_version'] = self.check_version(timeout=check_timeout)
  File "/home/airflow/.local/lib/python3.10/site-packages/kafka/client_async.py", line 900, in check_version
    raise Errors.NoBrokersAvailable()
kafka.errors.NoBrokersAvailable: NoBrokersAvailable

During handling of the above exception, another exception occurred:

Traceback (most recent call last):
  File "/home/airflow/.local/lib/python3.10/site-packages/airflow/models/taskinstance.py", line 762, in _execute_task
    result = _execute_callable(context=context, **execute_callable_kwargs)
  File "/home/airflow/.local/lib/python3.10/site-packages/airflow/models/taskinstance.py", line 733, in _execute_callable
    return ExecutionCallableRunner(
  File "/home/airflow/.local/lib/python3.10/site-packages/airflow/utils/operator_helpers.py", line 252, in run
    return self.func(*args, **kwargs)
  File "/home/airflow/.local/lib/python3.10/site-packages/airflow/models/baseoperator.py", line 406, in wrapper
    return func(self, *args, **kwargs)
  File "/home/airflow/.local/lib/python3.10/site-packages/airflow/operators/python.py", line 238, in execute
    return_value = self.execute_callable()
  File "/home/airflow/.local/lib/python3.10/site-packages/airflow/operators/python.py", line 256, in execute_callable
    return runner.run(*self.op_args, **self.op_kwargs)
  File "/home/airflow/.local/lib/python3.10/site-packages/airflow/utils/operator_helpers.py", line 252, in run
    return self.func(*args, **kwargs)
  File "/opt/airflow/dags/testlog_ml.py", line 149, in kafka_consumer
    consumer.close()
UnboundLocalError: local variable 'consumer' referenced before assignment
[2025-05-21T13:32:24.933+0000] {taskinstance.py:1225} INFO - Marking task as UP_FOR_RETRY. dag_id=kafka_to_minio_to_spark, task_id=kafka_consumer, run_id=scheduled__2025-05-20T16:00:00+00:00, execution_date=20250520T160000, start_date=20250521T133224, end_date=20250521T133224
[2025-05-21T13:32:24.939+0000] {taskinstance.py:340} INFO - ::group::Post task execution logs
[2025-05-21T13:32:24.939+0000] {standard_task_runner.py:124} ERROR - Failed to execute job 144 for task kafka_consumer (local variable 'consumer' referenced before assignment; 500)
Traceback (most recent call last):
  File "/opt/airflow/dags/testlog_ml.py", line 146, in kafka_consumer
    raise e
  File "/opt/airflow/dags/testlog_ml.py", line 82, in kafka_consumer
    consumer = KafkaConsumer(
  File "/home/airflow/.local/lib/python3.10/site-packages/kafka/consumer/group.py", line 356, in __init__
    self._client = KafkaClient(metrics=self._metrics, **self.config)
  File "/home/airflow/.local/lib/python3.10/site-packages/kafka/client_async.py", line 244, in __init__
    self.config['api_version'] = self.check_version(timeout=check_timeout)
  File "/home/airflow/.local/lib/python3.10/site-packages/kafka/client_async.py", line 900, in check_version
    raise Errors.NoBrokersAvailable()
kafka.errors.NoBrokersAvailable: NoBrokersAvailable

During handling of the above exception, another exception occurred:

Traceback (most recent call last):
  File "/home/airflow/.local/lib/python3.10/site-packages/airflow/task/task_runner/standard_task_runner.py", line 117, in _start_by_fork
    ret = args.func(args, dag=self.dag)
  File "/home/airflow/.local/lib/python3.10/site-packages/airflow/cli/cli_config.py", line 49, in command
    return func(*args, **kwargs)
  File "/home/airflow/.local/lib/python3.10/site-packages/airflow/utils/cli.py", line 115, in wrapper
    return f(*args, **kwargs)
  File "/home/airflow/.local/lib/python3.10/site-packages/airflow/cli/commands/task_command.py", line 483, in task_run
    task_return_code = _run_task_by_selected_method(args, _dag, ti)
  File "/home/airflow/.local/lib/python3.10/site-packages/airflow/cli/commands/task_command.py", line 256, in _run_task_by_selected_method
    return _run_raw_task(args, ti)
  File "/home/airflow/.local/lib/python3.10/site-packages/airflow/cli/commands/task_command.py", line 341, in _run_raw_task
    return ti._run_raw_task(
  File "/home/airflow/.local/lib/python3.10/site-packages/airflow/utils/session.py", line 97, in wrapper
    return func(*args, session=session, **kwargs)
  File "/home/airflow/.local/lib/python3.10/site-packages/airflow/models/taskinstance.py", line 3004, in _run_raw_task
    return _run_raw_task(
  File "/home/airflow/.local/lib/python3.10/site-packages/airflow/models/taskinstance.py", line 273, in _run_raw_task
    TaskInstance._execute_task_with_callbacks(
  File "/home/airflow/.local/lib/python3.10/site-packages/airflow/models/taskinstance.py", line 3158, in _execute_task_with_callbacks
    result = self._execute_task(context, task_orig)
  File "/home/airflow/.local/lib/python3.10/site-packages/airflow/models/taskinstance.py", line 3182, in _execute_task
    return _execute_task(self, context, task_orig)
  File "/home/airflow/.local/lib/python3.10/site-packages/airflow/models/taskinstance.py", line 762, in _execute_task
    result = _execute_callable(context=context, **execute_callable_kwargs)
  File "/home/airflow/.local/lib/python3.10/site-packages/airflow/models/taskinstance.py", line 733, in _execute_callable
    return ExecutionCallableRunner(
  File "/home/airflow/.local/lib/python3.10/site-packages/airflow/utils/operator_helpers.py", line 252, in run
    return self.func(*args, **kwargs)
  File "/home/airflow/.local/lib/python3.10/site-packages/airflow/models/baseoperator.py", line 406, in wrapper
    return func(self, *args, **kwargs)
  File "/home/airflow/.local/lib/python3.10/site-packages/airflow/operators/python.py", line 238, in execute
    return_value = self.execute_callable()
  File "/home/airflow/.local/lib/python3.10/site-packages/airflow/operators/python.py", line 256, in execute_callable
    return runner.run(*self.op_args, **self.op_kwargs)
  File "/home/airflow/.local/lib/python3.10/site-packages/airflow/utils/operator_helpers.py", line 252, in run
    return self.func(*args, **kwargs)
  File "/opt/airflow/dags/testlog_ml.py", line 149, in kafka_consumer
    consumer.close()
UnboundLocalError: local variable 'consumer' referenced before assignment
[2025-05-21T13:32:24.956+0000] {local_task_job_runner.py:266} INFO - Task exited with return code 1
[2025-05-21T13:32:24.965+0000] {taskinstance.py:3900} INFO - 0 downstream tasks scheduled from follow-on schedule check
[2025-05-21T13:32:24.966+0000] {local_task_job_runner.py:245} INFO - ::endgroup::
